Workbook

Sheet Раздел 0
B2: ФЕДЕРАЛЬНОЕ СТАТИСТИЧЕСКОЕ НАБЛЮДЕНИЕ
B4: КОНФИДЕНЦИАЛЬНОСТЬ ГАРАНТИРУЕТСЯ ПОЛУЧАТЕЛЕМ ИНФОРМАЦИИ
B6: Нарушение порядка предоставления первичных статистических данных или несвоевременное предоставление этих данных, либо предоставление недостоверных первичных статистических данных влечет ответственность, установленную Кодексом Российской Федерации об административных правонарушениях
B8: Обязанность предоставления административных данных предусмотрена статьей 8 Федерального закона от 29 ноября 2007 г. № 282-ФЗ «Об официальном статистическом учете и системе государственной статистики в Российской Федерации»
B10: СВЕДЕНИЯ ПО ПОДГОТОВКЕ СПОРТИВНОГО РЕЗЕРВА
B11: по состоянию на 31 декабря 20__ г.
B13: Предоставляют: | K13: Сроки предоставления | Q13: Форма № 5-ФК
B14: юридические лица – организации государственной, муниципальной и иной формы собственности (кроме субъектов малого и среднего предпринимательства), реализующие дополнительные образовательные программы спортивной подготовки или обеспечивающие подготовку спортивного резерва (полный перечень категорий респондентов приведен в указаниях по заполнению формы федерального статистического наблюдения): – исполнительно-распорядительным органам местного самоуправления муниципального образования, уполномоченному органу публичной власти федеральной территории «Сириус» (схема предоставления приведена в указаниях по заполнению формы); исполнительно-распорядительные органы местного самоуправления муниципального образования: – органам исполнительной власти субъектов Российской Федерации в области физической культуры и спорта; органы исполнительной власти субъектов Российской Федерации в области физической культуры и спорта, уполномоченный орган публичной власти федеральной территории «Сириус»: – Министерству спорта Российской Федерации. | K14: до 15 января после отчетного периода до 19 января после отчетного периода до 25 января после отчетного периода | Q14: Приказ Росстата: Об утверждении формы от _________ № ___ О внесении изменений (при наличии) от __________ № ___ от __________ № ___
Q16: Годовая
A20: 1 | B20: Наименование отчитывающейся организации | L20: Краткое наименование отчитывающейся организации
A21: 2 | B21: Почтовый адрес
B22: Муниципальный район | I22: Городской округ | M22: Муниципальный округ | S22: Сельское поселение
A23: 3
B24: Код формы по ОКУД | E24: Код
E25: отчитывающейся организации по ОКПО (для обособленного подразделения и головного подразделения юридического лица – идентификационный номер) | I25: Регистрационный номер лицензии на осуществление образовательной деятельности | M25: Код субъекта Российской Федерации | P25: Код ОКТМО | S25: Находится на территории сельского поселения Код: нет - 0, да - 1
A26: 4 | B26: 1 | E26: 2 | I26: 3 | M26: 4 | P26: 5 | S26: 6
A27: 5 | B27: 0609403

Sheet Раздел 1
B1: Раздел I. Число организаций, единица
B2: Ведомственная принадлежность | C2: № строки | D2: Число организаций и обособленных структурных подразделений – всего | E2: в том числе по наименованию организации:
E3: СШ | F3: СШОР | G3: УОР | H3: ЦСП | I3: Другие организации
B4: 1 | C4: 2 | D4: 3 | E4: 4 | F4: 5 | G4: 6 | H4: 7 | I4: 8
B5: Организации в ведении органов управления в сфере физической культуры и спорта | C5: 01 | D5: =E5+F5+G5+H5+I5 -> 1 | H5: 1
B6: Обособленные структурные подразделения в сфере физической культуры и спорта, реализующие дополнительные общеобразовательные программы в области физической культуры и спорта | C6: 02 | D6: =E6+F6+G6+H6+I6 -> 0
B7: Организации в ведении органов управления в сфере образования | C7: 03 | D7: =E7+F7+G7+H7+I7 -> 0
B8: Обособленные структурные подразделения в сфере образования, реализующие дополнительные общеобразовательные программы в области физической культуры и спорта | C8: 04 | D8: =E8+F8+G8+H8+I8 -> 0
B9: Организации другой ведомственной принадлежности | C9: 05 | D9: =E9+F9+G9+H9+I9 -> 0
B10: Обособленные структурные подразделения другой ведомственной принадлежности, реализующие дополнительные общеобразовательные программы в области физической культуры и спорта | C10: 06 | D10: =E10+F10+G10+H10+I10 -> 0
B11: Частные организации (из стр. 05) | C11: 07 | D11: =E11+F11+G11+H11+I11 -> 0
B12: Итого организаций | C12: 08 | D12: =D5+D7+D9 -> 1 | E12: =E5+E7+E9 -> 0 | F12: =F5+F7+F9 -> 0 | G12: =G5+G7+G9 -> 0 | H12: =H5+H7+H9 -> 1 | I12: =I5+I7+I9 -> 0
B13: Итого обособленных структурных подразделений, реализующих дополнительные общеобразовательные программы в области физической культуры и спорта | C13: 09 | D13: =D6+D8+D10 -> 0 | E13: =E6+E8+E10 -> 0 | F13: =F6+F8+F10 -> 0 | G13: =G6+G8+G10 -> 0 | H13: =H6+H8+H10 -> 0 | I13: =I6+I8+I10 -> 0
B15: ОГРН/для обособленных структурных подразделений ОГРН головной организации | C15: 10 | E15: =IF($D$12=1,$D$15,"") -> 0
B17: Виды правовых образований | C17: 11 | D17: Публичные правовые образования | H17: Иные правовые образования (в том числе частные)
D18: Российская Федерация | E18: Субъект Российской Федерации | F18: Муниципальное образование
A19: 11
B21: Наличие структурного подразделения интерната | C21: 12 | E21: Код: нет - 0, да - 1

Sheet Раздел 2
G5: Раздел II. Численность обучающихся
G6: Виды спорта | H6: № строки | I6: Число отделений по видам спорта, единица | J6: Базовый вид спорта, единица | K6: Численность обучающихся на 31 декабря отчетного периода, человек
K7: Итого обучающихся | L7: Обучающиеся по дополнительным общеобразовательным программам в области физической культуры и спорта
L8: Всего обучающихся по дополнительным образовательным программам спортивной подготовки | M8: по дополнительным образовательным программам спортивной подготовки | Q8: по возрастам (из гр. 6) | S8: по договорам платных образовательных услуг (из гр. 6) | X8: по дополнительным общеразвивающим программам (спортивно-оздоровительный этап) | Y8: по возрастам (из гр. 18) | AB8: по договорам платных образовательных услуг (из гр. 18) | AE8: из гр. 5:
A9: Код региона | B9: ОГРН | C9: Ведоственная принадлежность | D9: Вид организации | E9: ОСП | F9: Вид правового образования | M9: начальной подготовки | N9: учебно-тренировочный | O9: совершен-ствования спортивного мастерства | P9: высшего спортивного мастерства | Q9: 5-17 лет | R9: старше 18 лет | S9: начальной подготовки | T9: учебно - тренировочный | U9: совершен-ствования спортивного мастерства | V9: высшего спортивного мастерства | W9: в возрасте 5-17 лет (из гр. 11) | Y9: до 4 лет | Z9: 5-17 лет | AA9: старше 18 лет | AB9: до 4 лет | AC9: 5-17 лет | AD9: старше 18 лет | AE9: мальчиков, юношей, юниоров, мужчин | AF9: девочек, девушек, юниорок, женщин
A10: ='Раздел 0'!M27 -> 0 | B10: ='Раздел 1'!D15 -> 0 | C10: {=_xlfn.IFS(SUM('Раздел 1'!$D$5:$D$6)>0,"ФКиС",SUM('Раздел 1'!$D$7:$D$8)>0,"Образование",SUM('Раздел 1'!$D$9:$D$10)>0,"Другая")} -> ФКиС | D10: {=_xlfn.IFS(SUM('Раздел 1'!$E$12)>0,"СШ",SUM('Раздел 1'!$F$12)>0,"СШОР",SUM('Раздел 1'!$G$12)>0,"УОР",SUM('Раздел 1'!$H$12)>0,"ЦСП",SUM('Раздел 1'!$I$12)>0,"ДРУГИЕ",SUM('Раздел 1'!$E$13)>0,"ОСП СШ",SUM('Раздел 1'!$F$13)>0,"ОСП СШОР",SUM('Раздел 1'!$I$13)>0,"ОСП ДРУГИЕ")} -> ЦСП | E10: =IF(SUM('Раздел 1'!$D$12)>0,SUM('Раздел 1'!$D$13),"") -> 0 | F10: {=_xlfn.IFS(SUM('Раздел 1'!$D$19)>0,"РФ",SUM('Раздел 1'!$E$19)>0,"СУБЪЕКТ",SUM('Раздел 1'!$F$19:$G$19)>0,"МУНИЦИПАЛ",SUM('Раздел 1'!$H$19:$I$19)>0,"ИНЫЕ")} -> #N/A | G10: 1 | H10: 2 | I10: 3 | J10: 4 | K10: 5 | L10: 6 | M10: 7 | N10: 8 | O10: 9 | P10: 10 | Q10: 11 | R10: 12 | S10: 13 | T10: 14 | U10: 15 | V10: 16 | W10: 17 | X10: 18 | Y10: 19 | Z10: 20 | AA10: 21 | AB10: 22 | AC10: 23 | AD10: 24 | AE10: 25 | AF10: 26 | AG10: 27
G11: Авиамодельный спорт | H11: 01 | I11: 1 | K11: =L11+X11 -> 0 | L11: =SUM(M11:P11) -> 0 | AG11: =SUM(I11:AF11) -> 1
G12: Авиационные гонки | H12: 02 | K12: =L12+X12 -> 0 | L12: =SUM(M12:P12) -> 0 | AG12: =SUM(I12:AF12) -> 0
G13: Автомобильный спорт | H13: 03 | K13: =L13+X13 -> 0 | L13: =SUM(M13:P13) -> 0 | AG13: =SUM(I13:AF13) -> 0
G14: Автомодельный спорт | H14: 04 | K14: =L14+X14 -> 0 | L14: =SUM(M14:P14) -> 0 | AG14: =SUM(I14:AF14) -> 0
G15: Айкидо | H15: 05 | K15: =L15+X15 -> 0 | L15: =SUM(M15:P15) -> 0 | AG15: =SUM(I15:AF15) -> 0
G16: Акробатический рок-н-ролл | H16: 06 | K16: =L16+X16 -> 0 | L16: =SUM(M16:P16) -> 0 | AG16: =SUM(I16:AF16) -> 0
G17: Альпинизм - всего | H17: 07 | I17: =IF(SUM(I18:I19)>=1,1,0) -> 0 | K17: =L17+X17 -> 0 | L17: =SUM(M17:P17) -> 0 | M17: =SUM(M18:M19) -> 0 | N17: =SUM(N18:N19) -> 0 | O17: =SUM(O18:O19) -> 0 | P17: =SUM(P18:P19) -> 0 | Q17: =SUM(Q18:Q19) -> 0 | R17: =SUM(R18:R19) -> 0 | S17: =SUM(S18:S19) -> 0 | T17: =SUM(T18:T19) -> 0 | ... AF17: =SUM(AF18:AF19) -> 0 | AG17: =SUM(I17:AF17) -> 0
G18: в том числе: Ски-альпинизм | H18: 08 | K18: =L18+X18 -> 0 | L18: =SUM(M18:P18) -> 0 | AG18: =SUM(I18:AF18) -> 0
G19: Иные дисциплины вида спорта "альпинизм" | H19: 09 | K19: =L19+X19 -> 0 | L19: =SUM(M19:P19) -> 0 | AG19: =SUM(I19:AF19) -> 0
G20: Американский футбол | H20: 10 | K20: =L20+X20 -> 0 | L20: =SUM(M20:P20) -> 0 | AG20: =SUM(I20:AF20) -> 0
G21: Армейская высокоточная стрельба | H21: 11 | K21: =L21+X21 -> 0 | L21: =SUM(M21:P21) -> 0 | AG21: =SUM(I21:AF21) -> 0
G22: Армейский рукопашный бой | H22: 12 | K22: =L22+X22 -> 0 | L22: =SUM(M22:P22) -> 0 | AG22: =SUM(I22:AF22) -> 0
G23: Армейское тактико-стрелковое многоборье | H23: 13 | K23: =L23+X23 -> 0 | L23: =SUM(M23:P23) -> 0 | AG23: =SUM(I23:AF23) -> 0
G24: Армрестлинг | H24: 14 | K24: =L24+X24 -> 0 | L24: =SUM(M24:P24) -> 0 | AG24: =SUM(I24:AF24) -> 0
G25: Бадминтон | H25: 15 | K25: =L25+X25 -> 0 | L25: =SUM(M25:P25) -> 0 | AG25: =SUM(I25:AF25) -> 0
G26: Баскетбол - всего | H26: 16 | I26: =IF(SUM(I27:I30)>=1,1,0) -> 0 | K26: =L26+X26 -> 0 | L26: =SUM(M26:P26) -> 0 | M26: =SUM(M27:M30) -> 0 | N26: =SUM(N27:N30) -> 0 | O26: =SUM(O27:O30) -> 0 | P26: =SUM(P27:P30) -> 0 | Q26: =SUM(Q27:Q30) -> 0 | R26: =SUM(R27:R30) -> 0 | S26: =SUM(S27:S30) -> 0 | T26: =SUM(T27:T30) -> 0 | ... AF26: =SUM(AF27:AF30) -> 0 | AG26: =SUM(I26:AF26) -> 0
G27: в том числе: Баскетбол | H27: 17 | K27: =L27+X27 -> 0 | L27: =SUM(M27:P27) -> 0 | AG27: =SUM(I27:AF27) -> 0
G28: Баскетбол 3х3 | H28: 18 | K28: =L28+X28 -> 0 | L28: =SUM(M28:P28) -> 0 | AG28: =SUM(I28:AF28) -> 0
G29: Интерактивный баскетбол | H29: 19 | K29: =L29+X29 -> 0 | L29: =SUM(M29:P29) -> 0 | AG29: =SUM(I29:AF29) -> 0
G30: Иные дисциплины вида спорта "баскетбол" | H30: 20 | K30: =L30+X30 -> 0 | L30: =SUM(M30:P30) -> 0 | AG30: =SUM(I30:AF30) -> 0
G31: Бейсбол | H31: 21 | K31: =L31+X31 -> 0 | L31: =SUM(M31:P31) -> 0 | AG31: =SUM(I31:AF31) -> 0
G32: Биатлон | H32: 22 | K32: =L32+X32 -> 0 | L32: =SUM(M32:P32) -> 0 | AG32: =SUM(I32:AF32) -> 0
G33: Бильярдный спорт | H33: 23 | K33: =L33+X33 -> 0 | L33: =SUM(M33:P33) -> 0 | AG33: =SUM(I33:AF33) -> 0
G34: Бобслей - всего | H34: 24 | I34: =IF(SUM(I35:I38)>=1,1,0) -> 0 | K34: =L34+X34 -> 0 | L34: =SUM(M34:P34) -> 0 | M34: =SUM(M35:M38) -> 0 | N34: =SUM(N35:N38) -> 0 | O34: =SUM(O35:O38) -> 0 | P34: =SUM(P35:P38) -> 0 | Q34: =SUM(Q35:Q38) -> 0 | R34: =SUM(R35:R38) -> 0 | S34: =SUM(S35:S38) -> 0 | T34: =SUM(T35:T38) -> 0 | ... AF34: =SUM(AF35:AF38) -> 0 | AG34: =SUM(I34:AF34) -> 0
G35: в том числе: Скелетон | H35: 25 | K35: =L35+X35 -> 0 | L35: =SUM(M35:P35) -> 0 | AG35: =SUM(I35:AF35) -> 0
G36: Экипаж | H36: 26 | K36: =L36+X36 -> 0 | L36: =SUM(M36:P36) -> 0 | AG36: =SUM(I36:AF36) -> 0
G37: Монобоб | H37: 27 | K37: =L37+X37 -> 0 | L37: =SUM(M37:P37) -> 0 | AG37: =SUM(I37:AF37) -> 0
G38: Иные дисциплины вида спорта "бобслей" | H38: 28 | K38: =L38+X38 -> 0 | L38: =SUM(M38:P38) -> 0 | AG38: =SUM(I38:AF38) -> 0
G39: Бодибилдинг | H39: 29 | K39: =L39+X39 -> 0 | L39: =SUM(M39:P39) -> 0 | AG39: =SUM(I39:AF39) -> 0
G40: Бокс | H40: 30 | K40: =L40+X40 -> 0 | L40: =SUM(M40:P40) -> 0 | AG40: =SUM(I40:AF40) -> 0
G41: Борьба на поясах | H41: 31 | K41: =L41+X41 -> 0 | L41: =SUM(M41:P41) -> 0 | AG41: =SUM(I41:AF41) -> 0
G42: Боулинг | H42: 32 | K42: =L42+X42 -> 0 | L42: =SUM(M42:P42) -> 0 | AG42: =SUM(I42:AF42) -> 0
G43: Боулспорт | H43: 33 | K43: =L43+X43 -> 0 | L43: =SUM(M43:P43) -> 0 | AG43: =SUM(I43:AF43) -> 0
G44: Брейкинг | H44: 34 | K44: =L44+X44 -> 0 | L44: =SUM(M44:P44) -> 0 | AG44: =SUM(I44:AF44) -> 0
...

Sheet Раздел 3
G5: Раздел III. Численность обучающихся по дополнительным образовательным программам спортивной подготовки, человек
G6: Виды спорта | H6: № строки | I6: Численность обучающихся по дополнительным образовательным программам спортивной подготовки на 31 декабря отчетного периода (из гр.6 раздела II) | AC6: Численность обучающихся, зачисленных на дополнительные образовательные программы спортивной подготовки в отчетном периоде | AH6: Численность обучающихся, отчисленных с дополнительных образовательных программ спортивной подготовки в отчетном периоде
I7: Всего | J7: в том числе по этапам и годам подготовки | AC7: Всего | AD7: в том числе по этапам подготовки | AH7: Всего | AI7: в том числе по этапам подготовки
J8: начальной подготовки | M8: учебно-тренировочный | S8: совершенствования спортивного мастерства | X8: высшего спортивного мастерства
J9: 1 | K9: 2 | L9: более 2 | M9: 1 | N9: 2 | O9: 3 | P9: 4 | Q9: 5 | R9: более 5 | S9: 1 | T9: 2 | U9: 3 | V9: 4 | W9: более 4 | X9: 1 | Y9: 2 | Z9: 3 | AA9: 4 | AB9: более 4 | AD9: начальной подготовки | AE9: учебно-тренировочный | AF9: совершен-ствования спортивного мастерства | AG9: высшего спортивного мастерства | AI9: начальной подготовки | AJ9: учебно-тренировочный | AK9: совершен-ствования спортивного мастерства | AL9: высшего спортивного мастерства
A10: ='Раздел 0'!M27 -> 0 | B10: ='Раздел 1'!D15 -> 0 | C10: {=_xlfn.IFS(SUM('Раздел 1'!$D$5:$D$6)>0,"ФКиС",SUM('Раздел 1'!$D$7:$D$8)>0,"Образование",SUM('Раздел 1'!$D$9:$D$10)>0,"Другая")} -> ФКиС | D10: {=_xlfn.IFS(SUM('Раздел 1'!$E$12)>0,"СШ",SUM('Раздел 1'!$F$12)>0,"СШОР",SUM('Раздел 1'!$G$12)>0,"УОР",SUM('Раздел 1'!$H$12)>0,"ЦСП",SUM('Раздел 1'!$I$12)>0,"ДРУГИЕ",SUM('Раздел 1'!$E$13)>0,"ОСП СШ",SUM('Раздел 1'!$F$13)>0,"ОСП СШОР",SUM('Раздел 1'!$I$13)>0,"ОСП ДРУГИЕ")} -> ЦСП | E10: =IF(SUM('Раздел 1'!$D$12)>0,SUM('Раздел 1'!$D$13),"") -> 0 | F10: {=_xlfn.IFS(SUM('Раздел 1'!$D$19)>0,"РФ",SUM('Раздел 1'!$E$19)>0,"СУБЪЕКТ",SUM('Раздел 1'!$F$19:$G$19)>0,"МУНИЦИПАЛ",SUM('Раздел 1'!$H$19:$I$19)>0,"ИНЫЕ")} -> #N/A | G10: 1 | H10: 2 | I10: 3 | J10: 4 | K10: 5 | L10: 6 | M10: 7 | N10: 8 | O10: 9 | P10: 10 | Q10: 11 | R10: 12 | S10: 13 | T10: 14 | U10: 15 | V10: 16 | W10: 17 | X10: 18 | Y10: 19 | Z10: 20 | AA10: 21 | AB10: 22 | AC10: 23 | AD10: 24 | AE10: 25 | AF10: 26 | AG10: 27 | AH10: 28 | AI10: 29 | AJ10: 30 | AK10: 31 | AL10: 32 | AM10: 33
G11: Авиамодельный спорт | H11: 01 | I11: =SUM(J11:AB11) -> 0 | AC11: =SUM(AD11:AG11) -> 0 | AH11: =SUM(AI11:AL11) -> 0 | AM11: =SUM(J11:AL11) -> 0
G12: Авиационные гонки | H12: 02 | I12: =SUM(J12:AB12) -> 0 | AC12: =SUM(AD12:AG12) -> 0 | AH12: =SUM(AI12:AL12) -> 0 | AM12: =SUM(J12:AL12) -> 0
G13: Автомобильный спорт | H13: 03 | I13: =SUM(J13:AB13) -> 0 | AC13: =SUM(AD13:AG13) -> 0 | AH13: =SUM(AI13:AL13) -> 0 | AM13: =SUM(J13:AL13) -> 0
G14: Автомодельный спорт | H14: 04 | I14: =SUM(J14:AB14) -> 0 | AC14: =SUM(AD14:AG14) -> 0 | AH14: =SUM(AI14:AL14) -> 0 | AM14: =SUM(J14:AL14) -> 0
G15: Айкидо | H15: 05 | I15: =SUM(J15:AB15) -> 0 | AC15: =SUM(AD15:AG15) -> 0 | AH15: =SUM(AI15:AL15) -> 0 | AM15: =SUM(J15:AL15) -> 0
G16: Акробатический рок-н-ролл | H16: 06 | I16: =SUM(J16:AB16) -> 0 | AC16: =SUM(AD16:AG16) -> 0 | AH16: =SUM(AI16:AL16) -> 0 | AM16: =SUM(J16:AL16) -> 0
G17: Альпинизм - всего | H17: 07 | I17: =SUM(J17:AB17) -> 0 | J17: =SUM(J18:J19) -> 0 | K17: =SUM(K18:K19) -> 0 | L17: =SUM(L18:L19) -> 0 | M17: =SUM(M18:M19) -> 0 | N17: =SUM(N18:N19) -> 0 | O17: =SUM(O18:O19) -> 0 | P17: =SUM(P18:P19) -> 0 | Q17: =SUM(Q18:Q19) -> 0 | ... AB17: =SUM(AB18:AB19) -> 0 | AC17: =SUM(AD17:AG17) -> 0 | AD17: =SUM(AD18:AD19) -> 0 | AE17: =SUM(AE18:AE19) -> 0 | AF17: =SUM(AF18:AF19) -> 0 | AG17: =SUM(AG18:AG19) -> 0 | AH17: =SUM(AI17:AL17) -> 0 | AI17: =SUM(AI18:AI19) -> 0 | AJ17: =SUM(AJ18:AJ19) -> 0 | AK17: =SUM(AK18:AK19) -> 0 | AL17: =SUM(AL18:AL19) -> 0 | AM17: =SUM(J17:AL17) -> 0
G18: в том числе: Ски-альпинизм | H18: 08 | I18: =SUM(J18:AB18) -> 0 | AC18: =SUM(AD18:AG18) -> 0 | AH18: =SUM(AI18:AL18) -> 0 | AM18: =SUM(J18:AL18) -> 0
G19: Иные дисциплины вида спорта "альпинизм" | H19: 09 | I19: =SUM(J19:AB19) -> 0 | AC19: =SUM(AD19:AG19) -> 0 | AH19: =SUM(AI19:AL19) -> 0 | AM19: =SUM(J19:AL19) -> 0
G20: Американский футбол | H20: 10 | I20: =SUM(J20:AB20) -> 0 | AC20: =SUM(AD20:AG20) -> 0 | AH20: =SUM(AI20:AL20) -> 0 | AM20: =SUM(J20:AL20) -> 0
G21: Армейская высокоточная стрельба | H21: 11 | I21: =SUM(J21:AB21) -> 0 | AC21: =SUM(AD21:AG21) -> 0 | AH21: =SUM(AI21:AL21) -> 0 | AM21: =SUM(J21:AL21) -> 0
G22: Армейский рукопашный бой | H22: 12 | I22: =SUM(J22:AB22) -> 0 | AC22: =SUM(AD22:AG22) -> 0 | AH22: =SUM(AI22:AL22) -> 0 | AM22: =SUM(J22:AL22) -> 0
G23: Армейское тактико-стрелковое многоборье | H23: 13 | I23: =SUM(J23:AB23) -> 0 | AC23: =SUM(AD23:AG23) -> 0 | AH23: =SUM(AI23:AL23) -> 0 | AM23: =SUM(J23:AL23) -> 0
G24: Армрестлинг | H24: 14 | I24: =SUM(J24:AB24) -> 0 | AC24: =SUM(AD24:AG24) -> 0 | AH24: =SUM(AI24:AL24) -> 0 | AM24: =SUM(J24:AL24) -> 0
G25: Бадминтон | H25: 15 | I25: =SUM(J25:AB25) -> 0 | AC25: =SUM(AD25:AG25) -> 0 | AH25: =SUM(AI25:AL25) -> 0 | AM25: =SUM(J25:AL25) -> 0
G26: Баскетбол - всего | H26: 16 | I26: =SUM(J26:AB26) -> 0 | J26: =SUM(J27:J30) -> 0 | K26: =SUM(K27:K30) -> 0 | L26: =SUM(L27:L30) -> 0 | M26: =SUM(M27:M30) -> 0 | N26: =SUM(N27:N30) -> 0 | O26: =SUM(O27:O30) -> 0 | P26: =SUM(P27:P30) -> 0 | Q26: =SUM(Q27:Q30) -> 0 | ... AB26: =SUM(AB27:AB30) -> 0 | AC26: =SUM(AD26:AG26) -> 0 | AD26: =SUM(AD27:AD30) -> 0 | AE26: =SUM(AE27:AE30) -> 0 | AF26: =SUM(AF27:AF30) -> 0 | AG26: =SUM(AG27:AG30) -> 0 | AH26: =SUM(AI26:AL26) -> 0 | AI26: =SUM(AI27:AI30) -> 0 | AJ26: =SUM(AJ27:AJ30) -> 0 | AK26: =SUM(AK27:AK30) -> 0 | AL26: =SUM(AL27:AL30) -> 0 | AM26: =SUM(J26:AL26) -> 0
G27: в том числе: Баскетбол | H27: 17 | I27: =SUM(J27:AB27) -> 0 | AC27: =SUM(AD27:AG27) -> 0 | AH27: =SUM(AI27:AL27) -> 0 | AM27: =SUM(J27:AL27) -> 0
G28: Баскетбол 3х3 | H28: 18 | I28: =SUM(J28:AB28) -> 0 | AC28: =SUM(AD28:AG28) -> 0 | AH28: =SUM(AI28:AL28) -> 0 | AM28: =SUM(J28:AL28) -> 0
G29: Интерактивный баскетбол | H29: 19 | I29: =SUM(J29:AB29) -> 0 | AC29: =SUM(AD29:AG29) -> 0 | AH29: =SUM(AI29:AL29) -> 0 | AM29: =SUM(J29:AL29) -> 0
G30: Иные дисциплины вида спорта "баскетбол" | H30: 20 | I30: =SUM(J30:AB30) -> 0 | AC30: =SUM(AD30:AG30) -> 0 | AH30: =SUM(AI30:AL30) -> 0 | AM30: =SUM(J30:AL30) -> 0
G31: Бейсбол | H31: 21 | I31: =SUM(J31:AB31) -> 0 | AC31: =SUM(AD31:AG31) -> 0 | AH31: =SUM(AI31:AL31) -> 0 | AM31: =SUM(J31:AL31) -> 0
G32: Биатлон | H32: 22 | I32: =SUM(J32:AB32) -> 0 | AC32: =SUM(AD32:AG32) -> 0 | AH32: =SUM(AI32:AL32) -> 0 | AM32: =SUM(J32:AL32) -> 0
G33: Бильярдный спорт | H33: 23 | I33: =SUM(J33:AB33) -> 0 | AC33: =SUM(AD33:AG33) -> 0 | AH33: =SUM(AI33:AL33) -> 0 | AM33: =SUM(J33:AL33) -> 0
G34: Бобслей - всего | H34: 24 | I34: =SUM(J34:AB34) -> 0 | J34: =SUM(J35:J38) -> 0 | K34: =SUM(K35:K38) -> 0 | L34: =SUM(L35:L38) -> 0 | M34: =SUM(M35:M38) -> 0 | N34: =SUM(N35:N38) -> 0 | O34: =SUM(O35:O38) -> 0 | P34: =SUM(P35:P38) -> 0 | Q34: =SUM(Q35:Q38) -> 0 | ... AB34: =SUM(AB35:AB38) -> 0 | AC34: =SUM(AD34:AG34) -> 0 | AD34: =SUM(AD35:AD38) -> 0 | AE34: =SUM(AE35:AE38) -> 0 | AF34: =SUM(AF35:AF38) -> 0 | AG34: =SUM(AG35:AG38) -> 0 | AH34: =SUM(AI34:AL34) -> 0 | AI34: =SUM(AI35:AI38) -> 0 | AJ34: =SUM(AJ35:AJ38) -> 0 | AK34: =SUM(AK35:AK38) -> 0 | AL34: =SUM(AL35:AL38) -> 0 | AM34: =SUM(J34:AL34) -> 0
G35: в том числе: Скелетон | H35: 25 | I35: =SUM(J35:AB35) -> 0 | AC35: =SUM(AD35:AG35) -> 0 | AH35: =SUM(AI35:AL35) -> 0 | AM35: =SUM(J35:AL35) -> 0
G36: Экипаж | H36: 26 | I36: =SUM(J36:AB36) -> 0 | AC36: =SUM(AD36:AG36) -> 0 | AH36: =SUM(AI36:AL36) -> 0 | AM36: =SUM(J36:AL36) -> 0
G37: Монобоб | H37: 27 | I37: =SUM(J37:AB37) -> 0 | AC37: =SUM(AD37:AG37) -> 0 | AH37: =SUM(AI37:AL37) -> 0 | AM37: =SUM(J37:AL37) -> 0
G38: Иные дисциплины вида спорта "бобслей" | H38: 28 | I38: =SUM(J38:AB38) -> 0 | AC38: =SUM(AD38:AG38) -> 0 | AH38: =SUM(AI38:AL38) -> 0 | AM38: =SUM(J38:AL38) -> 0
G39: Бодибилдинг | H39: 29 | I39: =SUM(J39:AB39) -> 0 | AC39: =SUM(AD39:AG39) -> 0 | AH39: =SUM(AI39:AL39) -> 0 | AM39: =SUM(J39:AL39) -> 0
G40: Бокс | H40: 30 | I40: =SUM(J40:AB40) -> 0 | AC40: =SUM(AD40:AG40) -> 0 | AH40: =SUM(AI40:AL40) -> 0 | AM40: =SUM(J40:AL40) -> 0
G41: Борьба на поясах | H41: 31 | I41: =SUM(J41:AB41) -> 0 | AC41: =SUM(AD41:AG41) -> 0 | AH41: =SUM(AI41:AL41) -> 0 | AM41: =SUM(J41:AL41) -> 0
G42: Боулинг | H42: 32 | I42: =SUM(J42:AB42) -> 0 | AC42: =SUM(AD42:AG42) -> 0 | AH42: =SUM(AI42:AL42) -> 0 | AM42: =SUM(J42:AL42) -> 0
G43: Боулспорт | H43: 33 | I43: =SUM(J43:AB43) -> 0 | AC43: =SUM(AD43:AG43) -> 0 | AH43: =SUM(AI43:AL43) -> 0 | AM43: =SUM(J43:AL43) -> 0
G44: Брейкинг | H44: 34 | I44: =SUM(J44:AB44) -> 0 | AC44: =SUM(AD44:AG44) -> 0 | AH44: =SUM(AI44:AL44) -> 0 | AM44: =SUM(J44:AL44) -> 0
...

Sheet Раздел 4
G1: Раздел IV. Спортивные разряды, спортивные звания
G6: Виды спорта | H6: № строки | I6: Из численности обучающихся и спортсменов, спортсменов-инструкторов на ставках (гр.5 раздела II и стр. 05 раздела IX), имеющих разряды, звания, человек | U6: Разряды, звания, присвоенные в отчетном периоде, единица
I7: Итого | J7: спортивные разряды | P7: спортивные звания | U7: Итого | V7: спортивные разряды присвоенные | AB7: спортивные звания присвоенные
J8: Всего | K8: в том числе: | P8: Всего | Q8: в том числе: | V8: Всего | W8: в том числе: | AB8: Всего | AC8: в том числе:
K9: КМС | L9: 1 разряд | M9: 2 разряд | N9: 3 разряд | O9: юношеские разряды | Q9: ЗМС | R9: МСМК | S9: МС | T9: гроссмейстер | W9: КМС | X9: 1 разряд | Y9: 2 разряд | Z9: 3 разряд | AA9: юношеские разряды | AC9: ЗМС | AD9: МСМК | AE9: МС | AF9: гроссмейстер
A10: ='Раздел 0'!M27 -> 0 | B10: ='Раздел 1'!D15 -> 0 | C10: {=_xlfn.IFS(SUM('Раздел 1'!$D$5:$D$6)>0,"ФКиС",SUM('Раздел 1'!$D$7:$D$8)>0,"Образование",SUM('Раздел 1'!$D$9:$D$10)>0,"Другая")} -> ФКиС | D10: {=_xlfn.IFS(SUM('Раздел 1'!$E$12)>0,"СШ",SUM('Раздел 1'!$F$12)>0,"СШОР",SUM('Раздел 1'!$G$12)>0,"УОР",SUM('Раздел 1'!$H$12)>0,"ЦСП",SUM('Раздел 1'!$I$12)>0,"ДРУГИЕ",SUM('Раздел 1'!$E$13)>0,"ОСП СШ",SUM('Раздел 1'!$F$13)>0,"ОСП СШОР",SUM('Раздел 1'!$I$13)>0,"ОСП ДРУГИЕ")} -> ЦСП | E10: =IF(SUM('Раздел 1'!$D$12)>0,SUM('Раздел 1'!$D$13),"") -> 0 | F10: {=_xlfn.IFS(SUM('Раздел 1'!$D$19)>0,"РФ",SUM('Раздел 1'!$E$19)>0,"СУБЪЕКТ",SUM('Раздел 1'!$F$19:$G$19)>0,"МУНИЦИПАЛ",SUM('Раздел 1'!$H$19:$I$19)>0,"ИНЫЕ")} -> #N/A | G10: 1 | H10: 2 | I10: 3 | J10: 4 | K10: 5 | L10: 6 | M10: 7 | N10: 8 | O10: 9 | P10: 10 | Q10: 11 | R10: 12 | S10: 13 | T10: 14 | U10: 15 | V10: 16 | W10: 17 | X10: 18 | Y10: 19 | Z10: 20 | AA10: 21 | AB10: 22 | AC10: 23 | AD10: 24 | AE10: 25 | AF10: 26 | AG10: 27
G11: Авиамодельный спорт | H11: 01 | I11: =J11+P11 -> 0 | J11: =SUM(K11:O11) -> 0 | P11: =SUM(Q11:T11) -> 0 | U11: =V11+AB11 -> 0 | V11: =SUM(W11:AA11) -> 0 | AB11: =SUM(AC11:AF11) -> 0 | AG11: =SUM(I11:AF11) -> 0
G12: Авиационные гонки | H12: 02 | I12: =J12+P12 -> 0 | J12: =SUM(K12:O12) -> 0 | P12: =SUM(Q12:T12) -> 0 | U12: =V12+AB12 -> 0 | V12: =SUM(W12:AA12) -> 0 | AB12: =SUM(AC12:AF12) -> 0 | AG12: =SUM(I12:AF12) -> 0
G13: Автомобильный спорт | H13: 03 | I13: =J13+P13 -> 0 | J13: =SUM(K13:O13) -> 0 | P13: =SUM(Q13:T13) -> 0 | U13: =V13+AB13 -> 0 | V13: =SUM(W13:AA13) -> 0 | AB13: =SUM(AC13:AF13) -> 0 | AG13: =SUM(I13:AF13) -> 0
G14: Автомодельный спорт | H14: 04 | I14: =J14+P14 -> 0 | J14: =SUM(K14:O14) -> 0 | P14: =SUM(Q14:T14) -> 0 | U14: =V14+AB14 -> 0 | V14: =SUM(W14:AA14) -> 0 | AB14: =SUM(AC14:AF14) -> 0 | AG14: =SUM(I14:AF14) -> 0
G15: Айкидо | H15: 05 | I15: =J15+P15 -> 0 | J15: =SUM(K15:O15) -> 0 | P15: =SUM(Q15:T15) -> 0 | U15: =V15+AB15 -> 0 | V15: =SUM(W15:AA15) -> 0 | AB15: =SUM(AC15:AF15) -> 0 | AG15: =SUM(I15:AF15) -> 0
G16: Акробатический рок-н-ролл | H16: 06 | I16: =J16+P16 -> 0 | J16: =SUM(K16:O16) -> 0 | P16: =SUM(Q16:T16) -> 0 | U16: =V16+AB16 -> 0 | V16: =SUM(W16:AA16) -> 0 | AB16: =SUM(AC16:AF16) -> 0 | AG16: =SUM(I16:AF16) -> 0
G17: Альпинизм - всего | H17: 07 | I17: =J17+P17 -> 0 | J17: =SUM(K17:O17) -> 0 | K17: =SUM(K18:K19) -> 0 | L17: =SUM(L18:L19) -> 0 | M17: =SUM(M18:M19) -> 0 | N17: =SUM(N18:N19) -> 0 | O17: =SUM(O18:O19) -> 0 | P17: =SUM(Q17:T17) -> 0 | Q17: =SUM(Q18:Q19) -> 0 | R17: =SUM(R18:R19) -> 0 | S17: =SUM(S18:S19) -> 0 | T17: =SUM(T18:T19) -> 0 | U17: =V17+AB17 -> 0 | V17: =SUM(W17:AA17) -> 0 | W17: =SUM(W18:W19) -> 0 | X17: =SUM(X18:X19) -> 0 | Y17: =SUM(Y18:Y19) -> 0 | Z17: =SUM(Z18:Z19) -> 0 | AA17: =SUM(AA18:AA19) -> 0 | AB17: =SUM(AC17:AF17) -> 0 | AC17: =SUM(AC18:AC19) -> 0 | AD17: =SUM(AD18:AD19) -> 0 | AE17: =SUM(AE18:AE19) -> 0 | AF17: =SUM(AF18:AF19) -> 0 | AG17: =SUM(I17:AF17) -> 0
G18: в том числе: Ски-альпинизм | H18: 08 | I18: =J18+P18 -> 0 | J18: =SUM(K18:O18) -> 0 | P18: =SUM(Q18:T18) -> 0 | U18: =V18+AB18 -> 0 | V18: =SUM(W18:AA18) -> 0 | AB18: =SUM(AC18:AF18) -> 0 | AG18: =SUM(I18:AF18) -> 0
G19: Иные дисциплины вида спорта "альпинизм" | H19: 09 | I19: =J19+P19 -> 0 | J19: =SUM(K19:O19) -> 0 | P19: =SUM(Q19:T19) -> 0 | U19: =V19+AB19 -> 0 | V19: =SUM(W19:AA19) -> 0 | AB19: =SUM(AC19:AF19) -> 0 | AG19: =SUM(I19:AF19) -> 0
G20: Американский футбол | H20: 10 | I20: =J20+P20 -> 0 | J20: =SUM(K20:O20) -> 0 | P20: =SUM(Q20:T20) -> 0 | U20: =V20+AB20 -> 0 | V20: =SUM(W20:AA20) -> 0 | AB20: =SUM(AC20:AF20) -> 0 | AG20: =SUM(I20:AF20) -> 0
G21: Армейская высокоточная стрельба | H21: 11 | I21: =J21+P21 -> 0 | J21: =SUM(K21:O21) -> 0 | P21: =SUM(Q21:T21) -> 0 | U21: =V21+AB21 -> 0 | V21: =SUM(W21:AA21) -> 0 | AB21: =SUM(AC21:AF21) -> 0 | AG21: =SUM(I21:AF21) -> 0
G22: Армейский рукопашный бой | H22: 12 | I22: =J22+P22 -> 0 | J22: =SUM(K22:O22) -> 0 | P22: =SUM(Q22:T22) -> 0 | U22: =V22+AB22 -> 0 | V22: =SUM(W22:AA22) -> 0 | AB22: =SUM(AC22:AF22) -> 0 | AG22: =SUM(I22:AF22) -> 0
G23: Армейское тактико-стрелковое многоборье | H23: 13 | I23: =J23+P23 -> 0 | J23: =SUM(K23:O23) -> 0 | P23: =SUM(Q23:T23) -> 0 | U23: =V23+AB23 -> 0 | V23: =SUM(W23:AA23) -> 0 | AB23: =SUM(AC23:AF23) -> 0 | AG23: =SUM(I23:AF23) -> 0
G24: Армрестлинг | H24: 14 | I24: =J24+P24 -> 0 | J24: =SUM(K24:O24) -> 0 | P24: =SUM(Q24:T24) -> 0 | U24: =V24+AB24 -> 0 | V24: =SUM(W24:AA24) -> 0 | AB24: =SUM(AC24:AF24) -> 0 | AG24: =SUM(I24:AF24) -> 0
G25: Бадминтон | H25: 15 | I25: =J25+P25 -> 0 | J25: =SUM(K25:O25) -> 0 | P25: =SUM(Q25:T25) -> 0 | U25: =V25+AB25 -> 0 | V25: =SUM(W25:AA25) -> 0 | AB25: =SUM(AC25:AF25) -> 0 | AG25: =SUM(I25:AF25) -> 0
G26: Баскетбол - всего | H26: 16 | I26: =J26+P26 -> 0 | J26: =SUM(K26:O26) -> 0 | K26: =SUM(K27:K30) -> 0 | L26: =SUM(L27:L30) -> 0 | M26: =SUM(M27:M30) -> 0 | N26: =SUM(N27:N30) -> 0 | O26: =SUM(O27:O30) -> 0 | P26: =SUM(Q26:T26) -> 0 | Q26: =SUM(Q27:Q30) -> 0 | R26: =SUM(R27:R30) -> 0 | S26: =SUM(S27:S30) -> 0 | T26: =SUM(T27:T30) -> 0 | U26: =V26+AB26 -> 0 | V26: =SUM(W26:AA26) -> 0 | W26: =SUM(W27:W30) -> 0 | X26: =SUM(X27:X30) -> 0 | Y26: =SUM(Y27:Y30) -> 0 | Z26: =SUM(Z27:Z30) -> 0 | AA26: =SUM(AA27:AA30) -> 0 | AB26: =SUM(AC26:AF26) -> 0 | AC26: =SUM(AC27:AC30) -> 0 | AD26: =SUM(AD27:AD30) -> 0 | AE26: =SUM(AE27:AE30) -> 0 | AF26: =SUM(AF27:AF30) -> 0 | AG26: =SUM(I26:AF26) -> 0
G27: в том числе: Баскетбол | H27: 17 | I27: =J27+P27 -> 0 | J27: =SUM(K27:O27) -> 0 | P27: =SUM(Q27:T27) -> 0 | U27: =V27+AB27 -> 0 | V27: =SUM(W27:AA27) -> 0 | AB27: =SUM(AC27:AF27) -> 0 | AG27: =SUM(I27:AF27) -> 0
G28: Баскетбол 3х3 | H28: 18 | I28: =J28+P28 -> 0 | J28: =SUM(K28:O28) -> 0 | P28: =SUM(Q28:T28) -> 0 | U28: =V28+AB28 -> 0 | V28: =SUM(W28:AA28) -> 0 | AB28: =SUM(AC28:AF28) -> 0 | AG28: =SUM(I28:AF28) -> 0
G29: Интерактивный баскетбол | H29: 19 | I29: =J29+P29 -> 0 | J29: =SUM(K29:O29) -> 0 | P29: =SUM(Q29:T29) -> 0 | U29: =V29+AB29 -> 0 | V29: =SUM(W29:AA29) -> 0 | AB29: =SUM(AC29:AF29) -> 0 | AG29: =SUM(I29:AF29) -> 0
G30: Иные дисциплины вида спорта "баскетбол" | H30: 20 | I30: =J30+P30 -> 0 | J30: =SUM(K30:O30) -> 0 | P30: =SUM(Q30:T30) -> 0 | U30: =V30+AB30 -> 0 | V30: =SUM(W30:AA30) -> 0 | AB30: =SUM(AC30:AF30) -> 0 | AG30: =SUM(I30:AF30) -> 0
G31: Бейсбол | H31: 21 | I31: =J31+P31 -> 0 | J31: =SUM(K31:O31) -> 0 | P31: =SUM(Q31:T31) -> 0 | U31: =V31+AB31 -> 0 | V31: =SUM(W31:AA31) -> 0 | AB31: =SUM(AC31:AF31) -> 0 | AG31: =SUM(I31:AF31) -> 0
G32: Биатлон | H32: 22 | I32: =J32+P32 -> 0 | J32: =SUM(K32:O32) -> 0 | P32: =SUM(Q32:T32) -> 0 | U32: =V32+AB32 -> 0 | V32: =SUM(W32:AA32) -> 0 | AB32: =SUM(AC32:AF32) -> 0 | AG32: =SUM(I32:AF32) -> 0
G33: Бильярдный спорт | H33: 23 | I33: =J33+P33 -> 0 | J33: =SUM(K33:O33) -> 0 | P33: =SUM(Q33:T33) -> 0 | U33: =V33+AB33 -> 0 | V33: =SUM(W33:AA33) -> 0 | AB33: =SUM(AC33:AF33) -> 0 | AG33: =SUM(I33:AF33) -> 0
G34: Бобслей - всего | H34: 24 | I34: =J34+P34 -> 0 | J34: =SUM(K34:O34) -> 0 | K34: =SUM(K35:K38) -> 0 | L34: =SUM(L35:L38) -> 0 | M34: =SUM(M35:M38) -> 0 | N34: =SUM(N35:N38) -> 0 | O34: =SUM(O35:O38) -> 0 | P34: =SUM(Q34:T34) -> 0 | Q34: =SUM(Q35:Q38) -> 0 | R34: =SUM(R35:R38) -> 0 | S34: =SUM(S35:S38) -> 0 | T34: =SUM(T35:T38) -> 0 | U34: =V34+AB34 -> 0 | V34: =SUM(W34:AA34) -> 0 | W34: =SUM(W35:W38) -> 0 | X34: =SUM(X35:X38) -> 0 | Y34: =SUM(Y35:Y38) -> 0 | Z34: =SUM(Z35:Z38) -> 0 | AA34: =SUM(AA35:AA38) -> 0 | AB34: =SUM(AC34:AF34) -> 0 | AC34: =SUM(AC35:AC38) -> 0 | AD34: =SUM(AD35:AD38) -> 0 | AE34: =SUM(AE35:AE38) -> 0 | AF34: =SUM(AF35:AF38) -> 0 | AG34: =SUM(I34:AF34) -> 0
G35: в том числе: Скелетон | H35: 25 | I35: =J35+P35 -> 0 | J35: =SUM(K35:O35) -> 0 | P35: =SUM(Q35:T35) -> 0 | U35: =V35+AB35 -> 0 | V35: =SUM(W35:AA35) -> 0 | AB35: =SUM(AC35:AF35) -> 0 | AG35: =SUM(I35:AF35) -> 0
G36: Экипаж | H36: 26 | I36: =J36+P36 -> 0 | J36: =SUM(K36:O36) -> 0 | P36: =SUM(Q36:T36) -> 0 | U36: =V36+AB36 -> 0 | V36: =SUM(W36:AA36) -> 0 | AB36: =SUM(AC36:AF36) -> 0 | AG36: =SUM(I36:AF36) -> 0
G37: Монобоб | H37: 27 | I37: =J37+P37 -> 0 | J37: =SUM(K37:O37) -> 0 | P37: =SUM(Q37:T37) -> 0 | U37: =V37+AB37 -> 0 | V37: =SUM(W37:AA37) -> 0 | AB37: =SUM(AC37:AF37) -> 0 | AG37: =SUM(I37:AF37) -> 0
G38: Иные дисциплины вида спорта "бобслей" | H38: 28 | I38: =J38+P38 -> 0 | J38: =SUM(K38:O38) -> 0 | P38: =SUM(Q38:T38) -> 0 | U38: =V38+AB38 -> 0 | V38: =SUM(W38:AA38) -> 0 | AB38: =SUM(AC38:AF38) -> 0 | AG38: =SUM(I38:AF38) -> 0
G39: Бодибилдинг | H39: 29 | I39: =J39+P39 -> 0 | J39: =SUM(K39:O39) -> 0 | P39: =SUM(Q39:T39) -> 0 | U39: =V39+AB39 -> 0 | V39: =SUM(W39:AA39) -> 0 | AB39: =SUM(AC39:AF39) -> 0 | AG39: =SUM(I39:AF39) -> 0
G40: Бокс | H40: 30 | I40: =J40+P40 -> 0 | J40: =SUM(K40:O40) -> 0 | P40: =SUM(Q40:T40) -> 0 | U40: =V40+AB40 -> 0 | V40: =SUM(W40:AA40) -> 0 | AB40: =SUM(AC40:AF40) -> 0 | AG40: =SUM(I40:AF40) -> 0
G41: Борьба на поясах | H41: 31 | I41: =J41+P41 -> 0 | J41: =SUM(K41:O41) -> 0 | P41: =SUM(Q41:T41) -> 0 | U41: =V41+AB41 -> 0 | V41: =SUM(W41:AA41) -> 0 | AB41: =SUM(AC41:AF41) -> 0 | AG41: =SUM(I41:AF41) -> 0
G42: Боулинг | H42: 32 | I42: =J42+P42 -> 0 | J42: =SUM(K42:O42) -> 0 | P42: =SUM(Q42:T42) -> 0 | U42: =V42+AB42 -> 0 | V42: =SUM(W42:AA42) -> 0 | AB42: =SUM(AC42:AF42) -> 0 | AG42: =SUM(I42:AF42) -> 0
G43: Боулспорт | H43: 33 | I43: =J43+P43 -> 0 | J43: =SUM(K43:O43) -> 0 | P43: =SUM(Q43:T43) -> 0 | U43: =V43+AB43 -> 0 | V43: =SUM(W43:AA43) -> 0 | AB43: =SUM(AC43:AF43) -> 0 | AG43: =SUM(I43:AF43) -> 0
G44: Брейкинг | H44: 34 | I44: =J44+P44 -> 0 | J44: =SUM(K44:O44) -> 0 | P44: =SUM(Q44:T44) -> 0 | U44: =V44+AB44 -> 0 | V44: =SUM(W44:AA44) -> 0 | AB44: =SUM(AC44:AF44) -> 0 | AG44: =SUM(I44:AF44) -> 0
...

Sheet Раздел 5
G4: Раздел V. Кандидаты в спортивные сборные команды Российской Федерации, человек
G5: Виды спорта | H5: № строки | I5: Из численности обучающихся и спортсменов, спортсменов-инструкторов на ставках (гр. 5 раздела II и стр. 05 раздела IX) – кандидаты, состоящие в списках спортивных сборных команд | S5: Кандидаты, подготовленные в отчетном периоде
I6: Итого | J6: Юношеский состав | M6: Юниорский состав | P6: Основной состав | S6: Итого | T6: Юношеский состав | W6: Юниорский состав | Z6: Основной состав
J8: Всего по юношескому составу | K8: в том числе: | M8: Всего по юниорскому составу | N8: в том числе: | P8: Всего по основному составу | Q8: в том числе: | T8: Всего подготовлено по юношескому составу | U8: в том числе: | W8: Всего подготовлено по юниорскому составу | X8: в том числе: | Z8: Всего подготовлено по основному составу | AA8: в том числе:
K9: основной | L9: резерв | N9: основной | O9: резерв | Q9: основной | R9: резерв | U9: основной | V9: резерв | X9: основной | Y9: резерв | AA9: основной | AB9: резерв
A10: ='Раздел 0'!M27 -> 0 | B10: ='Раздел 1'!D15 -> 0 | C10: {=_xlfn.IFS(SUM('Раздел 1'!$D$5:$D$6)>0,"ФКиС",SUM('Раздел 1'!$D$7:$D$8)>0,"Образование",SUM('Раздел 1'!$D$9:$D$10)>0,"Другая")} -> ФКиС | D10: {=_xlfn.IFS(SUM('Раздел 1'!$E$12)>0,"СШ",SUM('Раздел 1'!$F$12)>0,"СШОР",SUM('Раздел 1'!$G$12)>0,"УОР",SUM('Раздел 1'!$H$12)>0,"ЦСП",SUM('Раздел 1'!$I$12)>0,"ДРУГИЕ",SUM('Раздел 1'!$E$13)>0,"ОСП СШ",SUM('Раздел 1'!$F$13)>0,"ОСП СШОР",SUM('Раздел 1'!$I$13)>0,"ОСП ДРУГИЕ")} -> ЦСП | E10: =IF(SUM('Раздел 1'!$D$12)>0,SUM('Раздел 1'!$D$13),"") -> 0 | F10: {=_xlfn.IFS(SUM('Раздел 1'!$D$19)>0,"РФ",SUM('Раздел 1'!$E$19)>0,"СУБЪЕКТ",SUM('Раздел 1'!$F$19:$G$19)>0,"МУНИЦИПАЛ",SUM('Раздел 1'!$H$19:$I$19)>0,"ИНЫЕ")} -> #N/A | G10: 1 | H10: 2 | I10: 3 | J10: 4 | K10: 5 | L10: 6 | M10: 7 | N10: 8 | O10: 9 | P10: 10 | Q10: 11 | R10: 12 | S10: 13 | T10: 14 | U10: 15 | V10: 16 | W10: 17 | X10: 18 | Y10: 19 | Z10: 20 | AA10: 21 | AB10: 22 | AC10: 23
G11: Авиамодельный спорт | H11: 01 | I11: =J11+M11+P11 -> 0 | J11: =K11+L11 -> 0 | M11: =N11+O11 -> 0 | P11: =Q11+R11 -> 0 | S11: =T11+W11+Z11 -> 0 | T11: =U11+V11 -> 0 | W11: =X11+Y11 -> 0 | Z11: =AA11+AB11 -> 0 | AC11: =SUM(I11:AB11) -> 0
G12: Авиационные гонки | H12: 02 | I12: =J12+M12+P12 -> 0 | J12: =K12+L12 -> 0 | M12: =N12+O12 -> 0 | P12: =Q12+R12 -> 0 | S12: =T12+W12+Z12 -> 0 | T12: =U12+V12 -> 0 | W12: =X12+Y12 -> 0 | Z12: =AA12+AB12 -> 0 | AC12: =SUM(I12:AB12) -> 0
G13: Автомобильный спорт | H13: 03 | I13: =J13+M13+P13 -> 0 | J13: =K13+L13 -> 0 | M13: =N13+O13 -> 0 | P13: =Q13+R13 -> 0 | S13: =T13+W13+Z13 -> 0 | T13: =U13+V13 -> 0 | W13: =X13+Y13 -> 0 | Z13: =AA13+AB13 -> 0 | AC13: =SUM(I13:AB13) -> 0
G14: Автомодельный спорт | H14: 04 | I14: =J14+M14+P14 -> 0 | J14: =K14+L14 -> 0 | M14: =N14+O14 -> 0 | P14: =Q14+R14 -> 0 | S14: =T14+W14+Z14 -> 0 | T14: =U14+V14 -> 0 | W14: =X14+Y14 -> 0 | Z14: =AA14+AB14 -> 0 | AC14: =SUM(I14:AB14) -> 0
G15: Айкидо | H15: 05 | I15: =J15+M15+P15 -> 0 | J15: =K15+L15 -> 0 | M15: =N15+O15 -> 0 | P15: =Q15+R15 -> 0 | S15: =T15+W15+Z15 -> 0 | T15: =U15+V15 -> 0 | W15: =X15+Y15 -> 0 | Z15: =AA15+AB15 -> 0 | AC15: =SUM(I15:AB15) -> 0
G16: Акробатический рок-н-ролл | H16: 06 | I16: =J16+M16+P16 -> 0 | J16: =K16+L16 -> 0 | M16: =N16+O16 -> 0 | P16: =Q16+R16 -> 0 | S16: =T16+W16+Z16 -> 0 | T16: =U16+V16 -> 0 | W16: =X16+Y16 -> 0 | Z16: =AA16+AB16 -> 0 | AC16: =SUM(I16:AB16) -> 0
G17: Альпинизм - всего | H17: 07 | I17: =J17+M17+P17 -> 0 | J17: =K17+L17 -> 0 | K17: =SUM(K18:K19) -> 0 | L17: =SUM(L18:L19) -> 0 | M17: =N17+O17 -> 0 | N17: =SUM(N18:N19) -> 0 | O17: =SUM(O18:O19) -> 0 | P17: =Q17+R17 -> 0 | Q17: =SUM(Q18:Q19) -> 0 | R17: =SUM(R18:R19) -> 0 | S17: =T17+W17+Z17 -> 0 | T17: =U17+V17 -> 0 | U17: =SUM(U18:U19) -> 0 | V17: =SUM(V18:V19) -> 0 | W17: =X17+Y17 -> 0 | X17: =SUM(X18:X19) -> 0 | Y17: =SUM(Y18:Y19) -> 0 | Z17: =AA17+AB17 -> 0 | AA17: =SUM(AA18:AA19) -> 0 | AB17: =SUM(AB18:AB19) -> 0 | AC17: =SUM(I17:AB17) -> 0
G18: в том числе: Ски-альпинизм | H18: 08 | I18: =J18+M18+P18 -> 0 | J18: =K18+L18 -> 0 | M18: =N18+O18 -> 0 | P18: =Q18+R18 -> 0 | S18: =T18+W18+Z18 -> 0 | T18: =U18+V18 -> 0 | W18: =X18+Y18 -> 0 | Z18: =AA18+AB18 -> 0 | AC18: =SUM(I18:AB18) -> 0
G19: Иные дисциплины вида спорта "альпинизм" | H19: 09 | I19: =J19+M19+P19 -> 0 | J19: =K19+L19 -> 0 | M19: =N19+O19 -> 0 | P19: =Q19+R19 -> 0 | S19: =T19+W19+Z19 -> 0 | T19: =U19+V19 -> 0 | W19: =X19+Y19 -> 0 | Z19: =AA19+AB19 -> 0 | AC19: =SUM(I19:AB19) -> 0
G20: Американский футбол | H20: 10 | I20: =J20+M20+P20 -> 0 | J20: =K20+L20 -> 0 | M20: =N20+O20 -> 0 | P20: =Q20+R20 -> 0 | S20: =T20+W20+Z20 -> 0 | T20: =U20+V20 -> 0 | W20: =X20+Y20 -> 0 | Z20: =AA20+AB20 -> 0 | AC20: =SUM(I20:AB20) -> 0
G21: Армейская высокоточная стрельба | H21: 11 | I21: =J21+M21+P21 -> 0 | J21: =K21+L21 -> 0 | M21: =N21+O21 -> 0 | P21: =Q21+R21 -> 0 | S21: =T21+W21+Z21 -> 0 | T21: =U21+V21 -> 0 | W21: =X21+Y21 -> 0 | Z21: =AA21+AB21 -> 0 | AC21: =SUM(I21:AB21) -> 0
G22: Армейский рукопашный бой | H22: 12 | I22: =J22+M22+P22 -> 0 | J22: =K22+L22 -> 0 | M22: =N22+O22 -> 0 | P22: =Q22+R22 -> 0 | S22: =T22+W22+Z22 -> 0 | T22: =U22+V22 -> 0 | W22: =X22+Y22 -> 0 | Z22: =AA22+AB22 -> 0 | AC22: =SUM(I22:AB22) -> 0
G23: Армейское тактико-стрелковое многоборье | H23: 13 | I23: =J23+M23+P23 -> 0 | J23: =K23+L23 -> 0 | M23: =N23+O23 -> 0 | P23: =Q23+R23 -> 0 | S23: =T23+W23+Z23 -> 0 | T23: =U23+V23 -> 0 | W23: =X23+Y23 -> 0 | Z23: =AA23+AB23 -> 0 | AC23: =SUM(I23:AB23) -> 0
G24: Армрестлинг | H24: 14 | I24: =J24+M24+P24 -> 0 | J24: =K24+L24 -> 0 | M24: =N24+O24 -> 0 | P24: =Q24+R24 -> 0 | S24: =T24+W24+Z24 -> 0 | T24: =U24+V24 -> 0 | W24: =X24+Y24 -> 0 | Z24: =AA24+AB24 -> 0 | AC24: =SUM(I24:AB24) -> 0
G25: Бадминтон | H25: 15 | I25: =J25+M25+P25 -> 0 | J25: =K25+L25 -> 0 | M25: =N25+O25 -> 0 | P25: =Q25+R25 -> 0 | S25: =T25+W25+Z25 -> 0 | T25: =U25+V25 -> 0 | W25: =X25+Y25 -> 0 | Z25: =AA25+AB25 -> 0 | AC25: =SUM(I25:AB25) -> 0
G26: Баскетбол - всего | H26: 16 | I26: =J26+M26+P26 -> 0 | J26: =K26+L26 -> 0 | K26: =SUM(K27:K30) -> 0 | L26: =SUM(L27:L30) -> 0 | M26: =N26+O26 -> 0 | N26: =SUM(N27:N30) -> 0 | O26: =SUM(O27:O30) -> 0 | P26: =Q26+R26 -> 0 | Q26: =SUM(Q27:Q30) -> 0 | R26: =SUM(R27:R30) -> 0 | S26: =T26+W26+Z26 -> 0 | T26: =U26+V26 -> 0 | U26: =SUM(U27:U30) -> 0 | V26: =SUM(V27:V30) -> 0 | W26: =X26+Y26 -> 0 | X26: =SUM(X27:X30) -> 0 | Y26: =SUM(Y27:Y30) -> 0 | Z26: =AA26+AB26 -> 0 | AA26: =SUM(AA27:AA30) -> 0 | AB26: =SUM(AB27:AB30) -> 0 | AC26: =SUM(I26:AB26) -> 0
G27: в том числе: Баскетбол | H27: 17 | I27: =J27+M27+P27 -> 0 | J27: =K27+L27 -> 0 | M27: =N27+O27 -> 0 | P27: =Q27+R27 -> 0 | S27: =T27+W27+Z27 -> 0 | T27: =U27+V27 -> 0 | W27: =X27+Y27 -> 0 | Z27: =AA27+AB27 -> 0 | AC27: =SUM(I27:AB27) -> 0
G28: Баскетбол 3х3 | H28: 18 | I28: =J28+M28+P28 -> 0 | J28: =K28+L28 -> 0 | M28: =N28+O28 -> 0 | P28: =Q28+R28 -> 0 | S28: =T28+W28+Z28 -> 0 | T28: =U28+V28 -> 0 | W28: =X28+Y28 -> 0 | Z28: =AA28+AB28 -> 0 | AC28: =SUM(I28:AB28) -> 0
G29: Интерактивный баскетбол | H29: 19 | I29: =J29+M29+P29 -> 0 | J29: =K29+L29 -> 0 | M29: =N29+O29 -> 0 | P29: =Q29+R29 -> 0 | S29: =T29+W29+Z29 -> 0 | T29: =U29+V29 -> 0 | W29: =X29+Y29 -> 0 | Z29: =AA29+AB29 -> 0 | AC29: =SUM(I29:AB29) -> 0
G30: Иные дисциплины вида спорта "баскетбол" | H30: 20 | I30: =J30+M30+P30 -> 0 | J30: =K30+L30 -> 0 | M30: =N30+O30 -> 0 | P30: =Q30+R30 -> 0 | S30: =T30+W30+Z30 -> 0 | T30: =U30+V30 -> 0 | W30: =X30+Y30 -> 0 | Z30: =AA30+AB30 -> 0 | AC30: =SUM(I30:AB30) -> 0
G31: Бейсбол | H31: 21 | I31: =J31+M31+P31 -> 0 | J31: =K31+L31 -> 0 | M31: =N31+O31 -> 0 | P31: =Q31+R31 -> 0 | S31: =T31+W31+Z31 -> 0 | T31: =U31+V31 -> 0 | W31: =X31+Y31 -> 0 | Z31: =AA31+AB31 -> 0 | AC31: =SUM(I31:AB31) -> 0
G32: Биатлон | H32: 22 | I32: =J32+M32+P32 -> 0 | J32: =K32+L32 -> 0 | M32: =N32+O32 -> 0 | P32: =Q32+R32 -> 0 | S32: =T32+W32+Z32 -> 0 | T32: =U32+V32 -> 0 | W32: =X32+Y32 -> 0 | Z32: =AA32+AB32 -> 0 | AC32: =SUM(I32:AB32) -> 0
G33: Бильярдный спорт | H33: 23 | I33: =J33+M33+P33 -> 0 | J33: =K33+L33 -> 0 | M33: =N33+O33 -> 0 | P33: =Q33+R33 -> 0 | S33: =T33+W33+Z33 -> 0 | T33: =U33+V33 -> 0 | W33: =X33+Y33 -> 0 | Z33: =AA33+AB33 -> 0 | AC33: =SUM(I33:AB33) -> 0
G34: Бобслей - всего | H34: 24 | I34: =J34+M34+P34 -> 0 | J34: =K34+L34 -> 0 | K34: =SUM(K35:K38) -> 0 | L34: =SUM(L35:L38) -> 0 | M34: =N34+O34 -> 0 | N34: =SUM(N35:N38) -> 0 | O34: =SUM(O35:O38) -> 0 | P34: =Q34+R34 -> 0 | Q34: =SUM(Q35:Q38) -> 0 | R34: =SUM(R35:R38) -> 0 | S34: =T34+W34+Z34 -> 0 | T34: =U34+V34 -> 0 | U34: =SUM(U35:U38) -> 0 | V34: =SUM(V35:V38) -> 0 | W34: =X34+Y34 -> 0 | X34: =SUM(X35:X38) -> 0 | Y34: =SUM(Y35:Y38) -> 0 | Z34: =AA34+AB34 -> 0 | AA34: =SUM(AA35:AA38) -> 0 | AB34: =SUM(AB35:AB38) -> 0 | AC34: =SUM(I34:AB34) -> 0
G35: в том числе: Скелетон | H35: 25 | I35: =J35+M35+P35 -> 0 | J35: =K35+L35 -> 0 | M35: =N35+O35 -> 0 | P35: =Q35+R35 -> 0 | S35: =T35+W35+Z35 -> 0 | T35: =U35+V35 -> 0 | W35: =X35+Y35 -> 0 | Z35: =AA35+AB35 -> 0 | AC35: =SUM(I35:AB35) -> 0
G36: Экипаж | H36: 26 | I36: =J36+M36+P36 -> 0 | J36: =K36+L36 -> 0 | M36: =N36+O36 -> 0 | P36: =Q36+R36 -> 0 | S36: =T36+W36+Z36 -> 0 | T36: =U36+V36 -> 0 | W36: =X36+Y36 -> 0 | Z36: =AA36+AB36 -> 0 | AC36: =SUM(I36:AB36) -> 0
G37: Монобоб | H37: 27 | I37: =J37+M37+P37 -> 0 | J37: =K37+L37 -> 0 | M37: =N37+O37 -> 0 | P37: =Q37+R37 -> 0 | S37: =T37+W37+Z37 -> 0 | T37: =U37+V37 -> 0 | W37: =X37+Y37 -> 0 | Z37: =AA37+AB37 -> 0 | AC37: =SUM(I37:AB37) -> 0
G38: Иные дисциплины вида спорта "бобслей" | H38: 28 | I38: =J38+M38+P38 -> 0 | J38: =K38+L38 -> 0 | M38: =N38+O38 -> 0 | P38: =Q38+R38 -> 0 | S38: =T38+W38+Z38 -> 0 | T38: =U38+V38 -> 0 | W38: =X38+Y38 -> 0 | Z38: =AA38+AB38 -> 0 | AC38: =SUM(I38:AB38) -> 0
G39: Бодибилдинг | H39: 29 | I39: =J39+M39+P39 -> 0 | J39: =K39+L39 -> 0 | M39: =N39+O39 -> 0 | P39: =Q39+R39 -> 0 | S39: =T39+W39+Z39 -> 0 | T39: =U39+V39 -> 0 | W39: =X39+Y39 -> 0 | Z39: =AA39+AB39 -> 0 | AC39: =SUM(I39:AB39) -> 0
G40: Бокс | H40: 30 | I40: =J40+M40+P40 -> 0 | J40: =K40+L40 -> 0 | M40: =N40+O40 -> 0 | P40: =Q40+R40 -> 0 | S40: =T40+W40+Z40 -> 0 | T40: =U40+V40 -> 0 | W40: =X40+Y40 -> 0 | Z40: =AA40+AB40 -> 0 | AC40: =SUM(I40:AB40) -> 0
G41: Борьба на поясах | H41: 31 | I41: =J41+M41+P41 -> 0 | J41: =K41+L41 -> 0 | M41: =N41+O41 -> 0 | P41: =Q41+R41 -> 0 | S41: =T41+W41+Z41 -> 0 | T41: =U41+V41 -> 0 | W41: =X41+Y41 -> 0 | Z41: =AA41+AB41 -> 0 | AC41: =SUM(I41:AB41) -> 0
G42: Боулинг | H42: 32 | I42: =J42+M42+P42 -> 0 | J42: =K42+L42 -> 0 | M42: =N42+O42 -> 0 | P42: =Q42+R42 -> 0 | S42: =T42+W42+Z42 -> 0 | T42: =U42+V42 -> 0 | W42: =X42+Y42 -> 0 | Z42: =AA42+AB42 -> 0 | AC42: =SUM(I42:AB42) -> 0
G43: Боулспорт | H43: 33 | I43: =J43+M43+P43 -> 0 | J43: =K43+L43 -> 0 | M43: =N43+O43 -> 0 | P43: =Q43+R43 -> 0 | S43: =T43+W43+Z43 -> 0 | T43: =U43+V43 -> 0 | W43: =X43+Y43 -> 0 | Z43: =AA43+AB43 -> 0 | AC43: =SUM(I43:AB43) -> 0
G44: Брейкинг | H44: 34 | I44: =J44+M44+P44 -> 0 | J44: =K44+L44 -> 0 | M44: =N44+O44 -> 0 | P44: =Q44+R44 -> 0 | S44: =T44+W44+Z44 -> 0 | T44: =U44+V44 -> 0 | W44: =X44+Y44 -> 0 | Z44: =AA44+AB44 -> 0 | AC44: =SUM(I44:AB44) -> 0
...

Sheet Раздел 6
G5: Раздел VI. Всероссийские спортивные соревнования, единица
G6: Виды спорта | H6: № строки | I6: Результаты выступлений на соревнованиях
I7: Всего | O7: Чемпионат России | T7: Первенство России среди юниоров и юниорок | Y7: Первенство России среди юношей и девушек | AD7: Кубок России | AI7: Всероссийские спартакиады между спортсменами субъектов Российской Федерации по летним и зимним видам спорта | AN7: Прочие официальные всероссийские соревнования
I9: медали (1-3 место) | J9: 1 | K9: 2 | L9: 3 | M9: 4-6 | N9: учас-тие | O9: 1 | P9: 2 | Q9: 3 | R9: 4-6 | S9: учас-тие | T9: 1 | U9: 2 | V9: 3 | W9: 4-6 | X9: учас-тие | Y9: 1 | Z9: 2 | AA9: 3 | AB9: 4-6 | AC9: учас-тие | AD9: 1 | AE9: 2 | AF9: 3 | AG9: 4-6 | AH9: учас-тие | AI9: 1 | AJ9: 2 | AK9: 3 | AL9: 4-6 | AM9: учас-тие | AN9: 1 | AO9: 2 | AP9: 3 | AQ9: 4-6 | AR9: учас-тие
A10: ='Раздел 0'!M27 -> 0 | B10: ='Раздел 1'!D15 -> 0 | C10: {=_xlfn.IFS(SUM('Раздел 1'!$D$5:$D$6)>0,"ФКиС",SUM('Раздел 1'!$D$7:$D$8)>0,"Образование",SUM('Раздел 1'!$D$9:$D$10)>0,"Другая")} -> ФКиС | D10: {=_xlfn.IFS(SUM('Раздел 1'!$E$12)>0,"СШ",SUM('Раздел 1'!$F$12)>0,"СШОР",SUM('Раздел 1'!$G$12)>0,"УОР",SUM('Раздел 1'!$H$12)>0,"ЦСП",SUM('Раздел 1'!$I$12)>0,"ДРУГИЕ",SUM('Раздел 1'!$E$13)>0,"ОСП СШ",SUM('Раздел 1'!$F$13)>0,"ОСП СШОР",SUM('Раздел 1'!$I$13)>0,"ОСП ДРУГИЕ")} -> ЦСП | E10: =IF(SUM('Раздел 1'!$D$12)>0,SUM('Раздел 1'!$D$13),"") -> 0 | F10: {=_xlfn.IFS(SUM('Раздел 1'!$D$19)>0,"РФ",SUM('Раздел 1'!$E$19)>0,"СУБЪЕКТ",SUM('Раздел 1'!$F$19:$G$19)>0,"МУНИЦИПАЛ",SUM('Раздел 1'!$H$19:$I$19)>0,"ИНЫЕ")} -> #N/A | G10: 1 | H10: 2 | I10: 3 | J10: 4 | K10: 5 | L10: 6 | M10: 7 | N10: 8 | O10: 9 | P10: 10 | Q10: 11 | R10: 12 | S10: 13 | T10: 14 | U10: 15 | V10: 16 | W10: 17 | X10: 18 | Y10: 19 | Z10: 20 | AA10: 21 | AB10: 22 | AC10: 23 | AD10: 24 | AE10: 25 | AF10: 26 | AG10: 27 | AH10: 28 | AI10: 29 | AJ10: 30 | AK10: 31 | AL10: 32 | AM10: 33 | AN10: 34 | AO10: 35 | AP10: 36 | AQ10: 37 | AR10: 38 | AS10: 39
F11: НЕОЛИМП | G11: Авиамодельный спорт | H11: 01 | I11: =SUM(J11:L11) -> 0 | J11: =O11+T11+Y11+AD11+AI11+AN11 -> 0 | K11: =P11+U11+Z11+AE11+AJ11+AO11 -> 0 | L11: =Q11+V11+AA11+AF11+AK11+AP11 -> 0 | M11: =R11+W11+AB11+AG11+AL11+AQ11 -> 0 | N11: =S11+X11+AC11+AH11+AM11+AR11 -> 0 | AS11: =SUM(I11:AR11) -> 0
F12: НЕОЛИМП | G12: Авиационные гонки | H12: 02 | I12: =SUM(J12:L12) -> 0 | J12: =O12+T12+Y12+AD12+AI12+AN12 -> 0 | K12: =P12+U12+Z12+AE12+AJ12+AO12 -> 0 | L12: =Q12+V12+AA12+AF12+AK12+AP12 -> 0 | M12: =R12+W12+AB12+AG12+AL12+AQ12 -> 0 | N12: =S12+X12+AC12+AH12+AM12+AR12 -> 0 | AS12: =SUM(I12:AR12) -> 0
F13: НЕОЛИМП | G13: Автомобильный спорт | H13: 03 | I13: =SUM(J13:L13) -> 0 | J13: =O13+T13+Y13+AD13+AI13+AN13 -> 0 | K13: =P13+U13+Z13+AE13+AJ13+AO13 -> 0 | L13: =Q13+V13+AA13+AF13+AK13+AP13 -> 0 | M13: =R13+W13+AB13+AG13+AL13+AQ13 -> 0 | N13: =S13+X13+AC13+AH13+AM13+AR13 -> 0 | AS13: =SUM(I13:AR13) -> 0
F14: НЕОЛИМП | G14: Автомодельный спорт | H14: 04 | I14: =SUM(J14:L14) -> 0 | J14: =O14+T14+Y14+AD14+AI14+AN14 -> 0 | K14: =P14+U14+Z14+AE14+AJ14+AO14 -> 0 | L14: =Q14+V14+AA14+AF14+AK14+AP14 -> 0 | M14: =R14+W14+AB14+AG14+AL14+AQ14 -> 0 | N14: =S14+X14+AC14+AH14+AM14+AR14 -> 0 | AS14: =SUM(I14:AR14) -> 0
F15: НЕОЛИМП | G15: Айкидо | H15: 05 | I15: =SUM(J15:L15) -> 0 | J15: =O15+T15+Y15+AD15+AI15+AN15 -> 0 | K15: =P15+U15+Z15+AE15+AJ15+AO15 -> 0 | L15: =Q15+V15+AA15+AF15+AK15+AP15 -> 0 | M15: =R15+W15+AB15+AG15+AL15+AQ15 -> 0 | N15: =S15+X15+AC15+AH15+AM15+AR15 -> 0 | AS15: =SUM(I15:AR15) -> 0
F16: НЕОЛИМП | G16: Акробатический рок-н-ролл | H16: 06 | I16: =SUM(J16:L16) -> 0 | J16: =O16+T16+Y16+AD16+AI16+AN16 -> 0 | K16: =P16+U16+Z16+AE16+AJ16+AO16 -> 0 | L16: =Q16+V16+AA16+AF16+AK16+AP16 -> 0 | M16: =R16+W16+AB16+AG16+AL16+AQ16 -> 0 | N16: =S16+X16+AC16+AH16+AM16+AR16 -> 0 | AS16: =SUM(I16:AR16) -> 0
F17: ОЛИМП зима | G17: Альпинизм - всего | H17: 07 | I17: =SUM(J17:L17) -> 0 | J17: =O17+T17+Y17+AD17+AI17+AN17 -> 0 | K17: =P17+U17+Z17+AE17+AJ17+AO17 -> 0 | L17: =Q17+V17+AA17+AF17+AK17+AP17 -> 0 | M17: =R17+W17+AB17+AG17+AL17+AQ17 -> 0 | N17: =S17+X17+AC17+AH17+AM17+AR17 -> 0 | O17: =SUM(O18:O19) -> 0 | P17: =SUM(P18:P19) -> 0 | Q17: =SUM(Q18:Q19) -> 0 | R17: =SUM(R18:R19) -> 0 | S17: =SUM(S18:S19) -> 0 | T17: =SUM(T18:T19) -> 0 | U17: =SUM(U18:U19) -> 0 | V17: =SUM(V18:V19) -> 0 | ... AR17: =SUM(AR18:AR19) -> 0 | AS17: =SUM(I17:AR17) -> 0
F18: ОЛИМП зима | G18: в том числе: Ски-альпинизм | H18: 08 | I18: =SUM(J18:L18) -> 0 | J18: =O18+T18+Y18+AD18+AI18+AN18 -> 0 | K18: =P18+U18+Z18+AE18+AJ18+AO18 -> 0 | L18: =Q18+V18+AA18+AF18+AK18+AP18 -> 0 | M18: =R18+W18+AB18+AG18+AL18+AQ18 -> 0 | N18: =S18+X18+AC18+AH18+AM18+AR18 -> 0 | AS18: =SUM(I18:AR18) -> 0
F19: ОЛИМП зима | G19: Иные дисциплины вида спорта "альпинизм" | H19: 09 | I19: =SUM(J19:L19) -> 0 | J19: =O19+T19+Y19+AD19+AI19+AN19 -> 0 | K19: =P19+U19+Z19+AE19+AJ19+AO19 -> 0 | L19: =Q19+V19+AA19+AF19+AK19+AP19 -> 0 | M19: =R19+W19+AB19+AG19+AL19+AQ19 -> 0 | N19: =S19+X19+AC19+AH19+AM19+AR19 -> 0 | AS19: =SUM(I19:AR19) -> 0
F20: ОЛИМП лето | G20: Американский футбол | H20: 10 | I20: =SUM(J20:L20) -> 0 | J20: =O20+T20+Y20+AD20+AI20+AN20 -> 0 | K20: =P20+U20+Z20+AE20+AJ20+AO20 -> 0 | L20: =Q20+V20+AA20+AF20+AK20+AP20 -> 0 | M20: =R20+W20+AB20+AG20+AL20+AQ20 -> 0 | N20: =S20+X20+AC20+AH20+AM20+AR20 -> 0 | AS20: =SUM(I20:AR20) -> 0
F21: ПРИКЛАДН | G21: Армейская высокоточная стрельба | H21: 11 | I21: =SUM(J21:L21) -> 0 | J21: =O21+T21+Y21+AD21+AI21+AN21 -> 0 | K21: =P21+U21+Z21+AE21+AJ21+AO21 -> 0 | L21: =Q21+V21+AA21+AF21+AK21+AP21 -> 0 | M21: =R21+W21+AB21+AG21+AL21+AQ21 -> 0 | N21: =S21+X21+AC21+AH21+AM21+AR21 -> 0 | AS21: =SUM(I21:AR21) -> 0
F22: ПРИКЛАДН | G22: Армейский рукопашный бой | H22: 12 | I22: =SUM(J22:L22) -> 0 | J22: =O22+T22+Y22+AD22+AI22+AN22 -> 0 | K22: =P22+U22+Z22+AE22+AJ22+AO22 -> 0 | L22: =Q22+V22+AA22+AF22+AK22+AP22 -> 0 | M22: =R22+W22+AB22+AG22+AL22+AQ22 -> 0 | N22: =S22+X22+AC22+AH22+AM22+AR22 -> 0 | AS22: =SUM(I22:AR22) -> 0
F23: ПРИКЛАДН | G23: Армейское тактико-стрелковое многоборье | H23: 13 | I23: =SUM(J23:L23) -> 0 | J23: =O23+T23+Y23+AD23+AI23+AN23 -> 0 | K23: =P23+U23+Z23+AE23+AJ23+AO23 -> 0 | L23: =Q23+V23+AA23+AF23+AK23+AP23 -> 0 | M23: =R23+W23+AB23+AG23+AL23+AQ23 -> 0 | N23: =S23+X23+AC23+AH23+AM23+AR23 -> 0 | AS23: =SUM(I23:AR23) -> 0
F24: НЕОЛИМП | G24: Армрестлинг | H24: 14 | I24: =SUM(J24:L24) -> 0 | J24: =O24+T24+Y24+AD24+AI24+AN24 -> 0 | K24: =P24+U24+Z24+AE24+AJ24+AO24 -> 0 | L24: =Q24+V24+AA24+AF24+AK24+AP24 -> 0 | M24: =R24+W24+AB24+AG24+AL24+AQ24 -> 0 | N24: =S24+X24+AC24+AH24+AM24+AR24 -> 0 | AS24: =SUM(I24:AR24) -> 0
F25: ОЛИМП лето | G25: Бадминтон | H25: 15 | I25: =SUM(J25:L25) -> 0 | J25: =O25+T25+Y25+AD25+AI25+AN25 -> 0 | K25: =P25+U25+Z25+AE25+AJ25+AO25 -> 0 | L25: =Q25+V25+AA25+AF25+AK25+AP25 -> 0 | M25: =R25+W25+AB25+AG25+AL25+AQ25 -> 0 | N25: =S25+X25+AC25+AH25+AM25+AR25 -> 0 | AS25: =SUM(I25:AR25) -> 0
F26: ОЛИМП лето | G26: Баскетбол - всего | H26: 16 | I26: =SUM(J26:L26) -> 0 | J26: =O26+T26+Y26+AD26+AI26+AN26 -> 0 | K26: =P26+U26+Z26+AE26+AJ26+AO26 -> 0 | L26: =Q26+V26+AA26+AF26+AK26+AP26 -> 0 | M26: =R26+W26+AB26+AG26+AL26+AQ26 -> 0 | N26: =S26+X26+AC26+AH26+AM26+AR26 -> 0 | O26: =SUM(O27:O30) -> 0 | P26: =SUM(P27:P30) -> 0 | Q26: =SUM(Q27:Q30) -> 0 | R26: =SUM(R27:R30) -> 0 | S26: =SUM(S27:S30) -> 0 | T26: =SUM(T27:T30) -> 0 | U26: =SUM(U27:U30) -> 0 | V26: =SUM(V27:V30) -> 0 | ... AR26: =SUM(AR27:AR30) -> 0 | AS26: =SUM(I26:AR26) -> 0
F27: ОЛИМП лето | G27: в том числе: Баскетбол | H27: 17 | I27: =SUM(J27:L27) -> 0 | J27: =O27+T27+Y27+AD27+AI27+AN27 -> 0 | K27: =P27+U27+Z27+AE27+AJ27+AO27 -> 0 | L27: =Q27+V27+AA27+AF27+AK27+AP27 -> 0 | M27: =R27+W27+AB27+AG27+AL27+AQ27 -> 0 | N27: =S27+X27+AC27+AH27+AM27+AR27 -> 0 | AS27: =SUM(I27:AR27) -> 0
F28: ОЛИМП лето | G28: Баскетбол 3х3 | H28: 18 | I28: =SUM(J28:L28) -> 0 | J28: =O28+T28+Y28+AD28+AI28+AN28 -> 0 | K28: =P28+U28+Z28+AE28+AJ28+AO28 -> 0 | L28: =Q28+V28+AA28+AF28+AK28+AP28 -> 0 | M28: =R28+W28+AB28+AG28+AL28+AQ28 -> 0 | N28: =S28+X28+AC28+AH28+AM28+AR28 -> 0 | AS28: =SUM(I28:AR28) -> 0
F29: ОЛИМП лето | G29: Интерактивный баскетбол | H29: 19 | I29: =SUM(J29:L29) -> 0 | J29: =O29+T29+Y29+AD29+AI29+AN29 -> 0 | K29: =P29+U29+Z29+AE29+AJ29+AO29 -> 0 | L29: =Q29+V29+AA29+AF29+AK29+AP29 -> 0 | M29: =R29+W29+AB29+AG29+AL29+AQ29 -> 0 | N29: =S29+X29+AC29+AH29+AM29+AR29 -> 0 | AS29: =SUM(I29:AR29) -> 0
F30: ОЛИМП лето | G30: Иные дисциплины вида спорта "баскетбол" | H30: 20 | I30: =SUM(J30:L30) -> 0 | J30: =O30+T30+Y30+AD30+AI30+AN30 -> 0 | K30: =P30+U30+Z30+AE30+AJ30+AO30 -> 0 | L30: =Q30+V30+AA30+AF30+AK30+AP30 -> 0 | M30: =R30+W30+AB30+AG30+AL30+AQ30 -> 0 | N30: =S30+X30+AC30+AH30+AM30+AR30 -> 0 | AS30: =SUM(I30:AR30) -> 0
F31: ОЛИМП лето | G31: Бейсбол | H31: 21 | I31: =SUM(J31:L31) -> 0 | J31: =O31+T31+Y31+AD31+AI31+AN31 -> 0 | K31: =P31+U31+Z31+AE31+AJ31+AO31 -> 0 | L31: =Q31+V31+AA31+AF31+AK31+AP31 -> 0 | M31: =R31+W31+AB31+AG31+AL31+AQ31 -> 0 | N31: =S31+X31+AC31+AH31+AM31+AR31 -> 0 | AS31: =SUM(I31:AR31) -> 0
F32: ОЛИМП зима | G32: Биатлон | H32: 22 | I32: =SUM(J32:L32) -> 0 | J32: =O32+T32+Y32+AD32+AI32+AN32 -> 0 | K32: =P32+U32+Z32+AE32+AJ32+AO32 -> 0 | L32: =Q32+V32+AA32+AF32+AK32+AP32 -> 0 | M32: =R32+W32+AB32+AG32+AL32+AQ32 -> 0 | N32: =S32+X32+AC32+AH32+AM32+AR32 -> 0 | AS32: =SUM(I32:AR32) -> 0
F33: НЕОЛИМП | G33: Бильярдный спорт | H33: 23 | I33: =SUM(J33:L33) -> 0 | J33: =O33+T33+Y33+AD33+AI33+AN33 -> 0 | K33: =P33+U33+Z33+AE33+AJ33+AO33 -> 0 | L33: =Q33+V33+AA33+AF33+AK33+AP33 -> 0 | M33: =R33+W33+AB33+AG33+AL33+AQ33 -> 0 | N33: =S33+X33+AC33+AH33+AM33+AR33 -> 0 | AS33: =SUM(I33:AR33) -> 0
F34: ОЛИМП зима | G34: Бобслей - всего | H34: 24 | I34: =SUM(J34:L34) -> 0 | J34: =O34+T34+Y34+AD34+AI34+AN34 -> 0 | K34: =P34+U34+Z34+AE34+AJ34+AO34 -> 0 | L34: =Q34+V34+AA34+AF34+AK34+AP34 -> 0 | M34: =R34+W34+AB34+AG34+AL34+AQ34 -> 0 | N34: =S34+X34+AC34+AH34+AM34+AR34 -> 0 | O34: =SUM(O35:O38) -> 0 | P34: =SUM(P35:P38) -> 0 | Q34: =SUM(Q35:Q38) -> 0 | R34: =SUM(R35:R38) -> 0 | S34: =SUM(S35:S38) -> 0 | T34: =SUM(T35:T38) -> 0 | U34: =SUM(U35:U38) -> 0 | V34: =SUM(V35:V38) -> 0 | ... AR34: =SUM(AR35:AR38) -> 0 | AS34: =SUM(I34:AR34) -> 0
F35: ОЛИМП зима | G35: в том числе: Скелетон | H35: 25 | I35: =SUM(J35:L35) -> 0 | J35: =O35+T35+Y35+AD35+AI35+AN35 -> 0 | K35: =P35+U35+Z35+AE35+AJ35+AO35 -> 0 | L35: =Q35+V35+AA35+AF35+AK35+AP35 -> 0 | M35: =R35+W35+AB35+AG35+AL35+AQ35 -> 0 | N35: =S35+X35+AC35+AH35+AM35+AR35 -> 0 | AS35: =SUM(I35:AR35) -> 0
F36: ОЛИМП зима | G36: Экипаж | H36: 26 | I36: =SUM(J36:L36) -> 0 | J36: =O36+T36+Y36+AD36+AI36+AN36 -> 0 | K36: =P36+U36+Z36+AE36+AJ36+AO36 -> 0 | L36: =Q36+V36+AA36+AF36+AK36+AP36 -> 0 | M36: =R36+W36+AB36+AG36+AL36+AQ36 -> 0 | N36: =S36+X36+AC36+AH36+AM36+AR36 -> 0 | AS36: =SUM(I36:AR36) -> 0
F37: ОЛИМП зима | G37: Монобоб | H37: 27 | I37: =SUM(J37:L37) -> 0 | J37: =O37+T37+Y37+AD37+AI37+AN37 -> 0 | K37: =P37+U37+Z37+AE37+AJ37+AO37 -> 0 | L37: =Q37+V37+AA37+AF37+AK37+AP37 -> 0 | M37: =R37+W37+AB37+AG37+AL37+AQ37 -> 0 | N37: =S37+X37+AC37+AH37+AM37+AR37 -> 0 | AS37: =SUM(I37:AR37) -> 0
F38: ОЛИМП зима | G38: Иные дисциплины вида спорта "бобслей" | H38: 28 | I38: =SUM(J38:L38) -> 0 | J38: =O38+T38+Y38+AD38+AI38+AN38 -> 0 | K38: =P38+U38+Z38+AE38+AJ38+AO38 -> 0 | L38: =Q38+V38+AA38+AF38+AK38+AP38 -> 0 | M38: =R38+W38+AB38+AG38+AL38+AQ38 -> 0 | N38: =S38+X38+AC38+AH38+AM38+AR38 -> 0 | AS38: =SUM(I38:AR38) -> 0
F39: НЕОЛИМП | G39: Бодибилдинг | H39: 29 | I39: =SUM(J39:L39) -> 0 | J39: =O39+T39+Y39+AD39+AI39+AN39 -> 0 | K39: =P39+U39+Z39+AE39+AJ39+AO39 -> 0 | L39: =Q39+V39+AA39+AF39+AK39+AP39 -> 0 | M39: =R39+W39+AB39+AG39+AL39+AQ39 -> 0 | N39: =S39+X39+AC39+AH39+AM39+AR39 -> 0 | AS39: =SUM(I39:AR39) -> 0
F40: ОЛИМП лето | G40: Бокс | H40: 30 | I40: =SUM(J40:L40) -> 0 | J40: =O40+T40+Y40+AD40+AI40+AN40 -> 0 | K40: =P40+U40+Z40+AE40+AJ40+AO40 -> 0 | L40: =Q40+V40+AA40+AF40+AK40+AP40 -> 0 | M40: =R40+W40+AB40+AG40+AL40+AQ40 -> 0 | N40: =S40+X40+AC40+AH40+AM40+AR40 -> 0 | AS40: =SUM(I40:AR40) -> 0
F41: НЕОЛИМП | G41: Борьба на поясах | H41: 31 | I41: =SUM(J41:L41) -> 0 | J41: =O41+T41+Y41+AD41+AI41+AN41 -> 0 | K41: =P41+U41+Z41+AE41+AJ41+AO41 -> 0 | L41: =Q41+V41+AA41+AF41+AK41+AP41 -> 0 | M41: =R41+W41+AB41+AG41+AL41+AQ41 -> 0 | N41: =S41+X41+AC41+AH41+AM41+AR41 -> 0 | AS41: =SUM(I41:AR41) -> 0
F42: НЕОЛИМП | G42: Боулинг | H42: 32 | I42: =SUM(J42:L42) -> 0 | J42: =O42+T42+Y42+AD42+AI42+AN42 -> 0 | K42: =P42+U42+Z42+AE42+AJ42+AO42 -> 0 | L42: =Q42+V42+AA42+AF42+AK42+AP42 -> 0 | M42: =R42+W42+AB42+AG42+AL42+AQ42 -> 0 | N42: =S42+X42+AC42+AH42+AM42+AR42 -> 0 | AS42: =SUM(I42:AR42) -> 0
F43: НЕОЛИМП | G43: Боулспорт | H43: 33 | I43: =SUM(J43:L43) -> 0 | J43: =O43+T43+Y43+AD43+AI43+AN43 -> 0 | K43: =P43+U43+Z43+AE43+AJ43+AO43 -> 0 | L43: =Q43+V43+AA43+AF43+AK43+AP43 -> 0 | M43: =R43+W43+AB43+AG43+AL43+AQ43 -> 0 | N43: =S43+X43+AC43+AH43+AM43+AR43 -> 0 | AS43: =SUM(I43:AR43) -> 0
F44: НЕОЛИМП | G44: Брейкинг | H44: 34 | I44: =SUM(J44:L44) -> 0 | J44: =O44+T44+Y44+AD44+AI44+AN44 -> 0 | K44: =P44+U44+Z44+AE44+AJ44+AO44 -> 0 | L44: =Q44+V44+AA44+AF44+AK44+AP44 -> 0 | M44: =R44+W44+AB44+AG44+AL44+AQ44 -> 0 | N44: =S44+X44+AC44+AH44+AM44+AR44 -> 0 | AS44: =SUM(I44:AR44) -> 0
F45: ОЛИМП лето | G45: Велосипедный спорт - всего | H45: 35 | I45: =SUM(J45:L45) -> 0 | J45: =O45+T45+Y45+AD45+AI45+AN45 -> 0 | K45: =P45+U45+Z45+AE45+AJ45+AO45 -> 0 | L45: =Q45+V45+AA45+AF45+AK45+AP45 -> 0 | M45: =R45+W45+AB45+AG45+AL45+AQ45 -> 0 | N45: =S45+X45+AC45+AH45+AM45+AR45 -> 0 | O45: =SUM(O46:O51) -> 0 | P45: =SUM(P46:P51) -> 0 | Q45: =SUM(Q46:Q51) -> 0 | R45: =SUM(R46:R51) -> 0 | S45: =SUM(S46:S51) -> 0 | T45: =SUM(T46:T51) -> 0 | U45: =SUM(U46:U51) -> 0 | V45: =SUM(V46:V51) -> 0 | ... AR45: =SUM(AR46:AR51) -> 0 | AS45: =SUM(I45:AR45) -> 0
...

Sheet Раздел 7
G5: Раздел VII. Международные спортивные соревнования, единица
G6: Виды спорта | H6: № строки | I6: Результаты выступлений на соревнованиях
I7: Всего | O7: Олимпийские игры | T7: Чемпионат мира | Y7: Юношеские Олимпийские игры | AD7: Первенство мира | AI7: Кубок мира | AN7: Этапы Кубка мира | AS7: Чемпионат Европы | AX7: Первенство Европы | BC7: Кубок Европы | BH7: Прочие официальные международные соревнования
I9: медали (1-3 место) | J9: 1 | K9: 2 | L9: 3 | M9: 4-6 | N9: учас-тие | O9: 1 | P9: 2 | Q9: 3 | R9: 4-6 | S9: учас-тие | T9: 1 | U9: 2 | V9: 3 | W9: 4-6 | X9: учас-тие | Y9: 1 | Z9: 2 | AA9: 3 | AB9: 4-6 | AC9: учас-тие | AD9: 1 | AE9: 2 | AF9: 3 | AG9: 4-6 | AH9: учас-тие | AI9: 1 | AJ9: 2 | AK9: 3 | AL9: 4-6 | AM9: учас-тие | AN9: 1 | AO9: 2 | AP9: 3 | AQ9: 4-6 | AR9: учас-тие | AS9: 1 | AT9: 2 | AU9: 3 | AV9: 4-6 | AW9: учас-тие | AX9: 1 | AY9: 2 | AZ9: 3 | BA9: 4-6 | BB9: учас-тие | BC9: 1 | BD9: 2 | BE9: 3 | BF9: 4-6 | BG9: учас-тие | BH9: 1 | BI9: 2 | BJ9: 3 | BK9: 4-6 | BL9: учас-тие
A10: ='Раздел 0'!M27 -> 0 | B10: ='Раздел 1'!D15 -> 0 | C10: {=_xlfn.IFS(SUM('Раздел 1'!$D$5:$D$6)>0,"ФКиС",SUM('Раздел 1'!$D$7:$D$8)>0,"Образование",SUM('Раздел 1'!$D$9:$D$10)>0,"Другая")} -> ФКиС | D10: {=_xlfn.IFS(SUM('Раздел 1'!$E$12)>0,"СШ",SUM('Раздел 1'!$F$12)>0,"СШОР",SUM('Раздел 1'!$G$12)>0,"УОР",SUM('Раздел 1'!$H$12)>0,"ЦСП",SUM('Раздел 1'!$I$12)>0,"ДРУГИЕ",SUM('Раздел 1'!$E$13)>0,"ОСП СШ",SUM('Раздел 1'!$F$13)>0,"ОСП СШОР",SUM('Раздел 1'!$I$13)>0,"ОСП ДРУГИЕ")} -> ЦСП | E10: =IF(SUM('Раздел 1'!$D$12)>0,SUM('Раздел 1'!$D$13),"") -> 0 | F10: {=_xlfn.IFS(SUM('Раздел 1'!$D$19)>0,"РФ",SUM('Раздел 1'!$E$19)>0,"СУБЪЕКТ",SUM('Раздел 1'!$F$19:$G$19)>0,"МУНИЦИПАЛ",SUM('Раздел 1'!$H$19:$I$19)>0,"ИНЫЕ")} -> #N/A | G10: 1 | H10: 2 | I10: 3 | J10: 4 | K10: 5 | L10: 6 | M10: 7 | N10: 8 | O10: 9 | P10: 10 | Q10: 11 | R10: 12 | S10: 13 | T10: 14 | U10: 15 | V10: 16 | W10: 17 | X10: 18 | Y10: 19 | Z10: 20 | AA10: 21 | AB10: 22 | AC10: 23 | AD10: 24 | AE10: 25 | AF10: 26 | AG10: 27 | AH10: 28 | AI10: 29 | AJ10: 30 | AK10: 31 | AL10: 32 | AM10: 33 | AN10: 34 | AO10: 35 | AP10: 36 | AQ10: 37 | AR10: 38 | AS10: 39 | AT10: 40 | AU10: 41 | AV10: 42 | AW10: 43 | AX10: 44 | AY10: 45 | AZ10: 46 | BA10: 47 | BB10: 48 | BC10: 49 | BD10: 50 | BE10: 51 | BF10: 52 | BG10: 53 | BH10: 54 | BI10: 55 | BJ10: 56 | BK10: 57 | BL10: 58 | BM10: 59
F11: НЕОЛИМП | G11: Авиамодельный спорт | H11: 01 | I11: =SUM(J11:L11) -> 0 | J11: =O11+T11+Y11+AD11+AI11+AN11+AS11+AX11+BC11+BH11 -> 0 | K11: =P11+U11+Z11+AE11+AJ11+AO11+AT11+AY11+BD11+BI11 -> 0 | L11: =Q11+V11+AA11+AF11+AK11+AP11+AU11+AZ11+BE11+BJ11 -> 0 | M11: =R11+W11+AB11+AG11+AL11+AQ11+AV11+BA11+BF11+BK11 -> 0 | N11: =S11+X11+AC11+AH11+AM11+AR11+AW11+BB11+BG11+BL11 -> 0 | BM11: =SUM(I11:BL11) -> 0
F12: НЕОЛИМП | G12: Авиационные гонки | H12: 02 | I12: =SUM(J12:L12) -> 0 | J12: =O12+T12+Y12+AD12+AI12+AN12+AS12+AX12+BC12+BH12 -> 0 | K12: =P12+U12+Z12+AE12+AJ12+AO12+AT12+AY12+BD12+BI12 -> 0 | L12: =Q12+V12+AA12+AF12+AK12+AP12+AU12+AZ12+BE12+BJ12 -> 0 | M12: =R12+W12+AB12+AG12+AL12+AQ12+AV12+BA12+BF12+BK12 -> 0 | N12: =S12+X12+AC12+AH12+AM12+AR12+AW12+BB12+BG12+BL12 -> 0 | BM12: =SUM(I12:BL12) -> 0
F13: НЕОЛИМП | G13: Автомобильный спорт | H13: 03 | I13: =SUM(J13:L13) -> 0 | J13: =O13+T13+Y13+AD13+AI13+AN13+AS13+AX13+BC13+BH13 -> 0 | K13: =P13+U13+Z13+AE13+AJ13+AO13+AT13+AY13+BD13+BI13 -> 0 | L13: =Q13+V13+AA13+AF13+AK13+AP13+AU13+AZ13+BE13+BJ13 -> 0 | M13: =R13+W13+AB13+AG13+AL13+AQ13+AV13+BA13+BF13+BK13 -> 0 | N13: =S13+X13+AC13+AH13+AM13+AR13+AW13+BB13+BG13+BL13 -> 0 | BM13: =SUM(I13:BL13) -> 0
